Workbook

Sheet Dashboard
A1: 🍽️ Food Market — รายงานยอดขาย พฤษภาคม 2569
A2: Python → Data sheet → Dashboard อัปเดตอัตโนมัติ • SUMIFS บน Item_Code + Branch
A4: รวมทุกสาขา | C4: อโศก | E4: พระราม 3 | G4: แฟชั่น 3 | I4: แฟชั่น B | K4: เอสพลานาด | M4: ขายเงินสด
A5: =SUM(C5,E5,G5,I5,K5,M5) | C5: =IFERROR(SUMIFS(Data!$G:$G,Data!$B:$B,"อโศก",Data!$A:$A,">="&DATE(2026,5,1),Data!$A:$A,"<="&DATE(2026,5,31)),0) | E5: =IFERROR(SUMIFS(Data!$G:$G,Data!$B:$B,"พระราม 3",Data!$A:$A,">="&DATE(2026,5,1),Data!$A:$A,"<="&DATE(2026,5,31)),0) | G5: =IFERROR(SUMIFS(Data!$G:$G,Data!$B:$B,"แฟชั่น 3",Data!$A:$A,">="&DATE(2026,5,1),Data!$A:$A,"<="&DATE(2026,5,31)),0) | I5: =IFERROR(SUMIFS(Data!$G:$G,Data!$B:$B,"แฟชั่น B",Data!$A:$A,">="&DATE(2026,5,1),Data!$A:$A,"<="&DATE(2026,5,31)),0) | K5: =IFERROR(SUMIFS(Data!$G:$G,Data!$B:$B,"เอสพลานาด",Data!$A:$A,">="&DATE(2026,5,1),Data!$A:$A,"<="&DATE(2026,5,31)),0) | M5: =IFERROR(SUMIFS(Data!$G:$G,Data!$B:$B,"ขายเงินสด",Data!$A:$A,">="&DATE(2026,5,1),Data!$A:$A,"<="&DATE(2026,5,31)),0)
A6: ฿ | C6: ฿ | E6: ฿ | G6: ฿ | I6: ฿ | K6: ฿ | M6: ฿
A8: สาขา | B8: ศ 1/5 | C8: ส 2/5 | D8: อา 3/5 | E8: จ 4/5 | F8: อ 5/5 | G8: พ 6/5 | H8: พฤ 7/5 | I8: ศ 8/5 | J8: ส 9/5 | K8: อา 10/5 | L8: จ 11/5 | M8: อ 12/5 | N8: พ 13/5 | O8: พฤ 14/5 | P8: ศ 15/5 | Q8: ส 16/5 | R8: อา 17/5 | S8: จ 18/5 | T8: อ 19/5 | U8: พ 20/5 | V8: พฤ 21/5 | W8: ศ 22/5 | X8: ส 23/5 | Y8: อา 24/5 | Z8: จ 25/5 | AA8: อ 26/5 | AB8: พ 27/5 | AC8: พฤ 28/5 | AD8: ศ 29/5 | AE8: ส 30/5 | AF8: อา 31/5 | AG8: รวม (฿) | AH8: %
A9: อโศก | B9: =IFERROR(SUMIFS(Data!$G:$G,Data!$B:$B,"อโศก",Data!$A:$A,DATE(2026,5,1)),"—") | C9: =IFERROR(SUMIFS(Data!$G:$G,Data!$B:$B,"อโศก",Data!$A:$A,DATE(2026,5,2)),"—") | D9: =IFERROR(SUMIFS(Data!$G:$G,Data!$B:$B,"อโศก",Data!$A:$A,DATE(2026,5,3)),"—") | E9: =IFERROR(SUMIFS(Data!$G:$G,Data!$B:$B,"อโศก",Data!$A:$A,DATE(2026,5,4)),"—") | F9: =IFERROR(SUMIFS(Data!$G:$G,Data!$B:$B,"อโศก",Data!$A:$A,DATE(2026,5,5)),"—") | G9: =IFERROR(SUMIFS(Data!$G:$G,Data!$B:$B,"อโศก",Data!$A:$A,DATE(2026,5,6)),"—") | H9: =IFERROR(SUMIFS(Data!$G:$G,Data!$B:$B,"อโศก",Data!$A:$A,DATE(2026,5,7)),"—") | I9: =IFERROR(SUMIFS(Data!$G:$G,Data!$B:$B,"อโศก",Data!$A:$A,DATE(2026,5,8)),"—") | J9: =IFERROR(SUMIFS(Data!$G:$G,Data!$B:$B,"อโศก",Data!$A:$A,DATE(2026,5,9)),"—") | K9: =IFERROR(SUMIFS(Data!$G:$G,Data!$B:$B,"อโศก",Data!$A:$A,DATE(2026,5,10)),"—") | L9: =IFERROR(SUMIFS(Data!$G:$G,Data!$B:$B,"อโศก",Data!$A:$A,DATE(2026,5,11)),"—") | M9: =IFERROR(SUMIFS(Data!$G:$G,Data!$B:$B,"อโศก",Data!$A:$A,DATE(2026,5,12)),"—") | N9: =IFERROR(SUMIFS(Data!$G:$G,Data!$B:$B,"อโศก",Data!$A:$A,DATE(2026,5,13)),"—") | O9: =IFERROR(SUMIFS(Data!$G:$G,Data!$B:$B,"อโศก",Data!$A:$A,DATE(2026,5,14)),"—") | P9: =IFERROR(SUMIFS(Data!$G:$G,Data!$B:$B,"อโศก",Data!$A:$A,DATE(2026,5,15)),"—") | Q9: =IFERROR(SUMIFS(Data!$G:$G,Data!$B:$B,"อโศก",Data!$A:$A,DATE(2026,5,16)),"—") | R9: =IFERROR(SUMIFS(Data!$G:$G,Data!$B:$B,"อโศก",Data!$A:$A,DATE(2026,5,17)),"—") | S9: =IFERROR(SUMIFS(Data!$G:$G,Data!$B:$B,"อโศก",Data!$A:$A,DATE(2026,5,18)),"—") | T9: =IFERROR(SUMIFS(Data!$G:$G,Data!$B:$B,"อโศก",Data!$A:$A,DATE(2026,5,19)),"—") | U9: =IFERROR(SUMIFS(Data!$G:$G,Data!$B:$B,"อโศก",Data!$A:$A,DATE(2026,5,20)),"—") | V9: =IFERROR(SUMIFS(Data!$G:$G,Data!$B:$B,"อโศก",Data!$A:$A,DATE(2026,5,21)),"—") | W9: =IFERROR(SUMIFS(Data!$G:$G,Data!$B:$B,"อโศก",Data!$A:$A,DATE(2026,5,22)),"—") | X9: =IFERROR(SUMIFS(Data!$G:$G,Data!$B:$B,"อโศก",Data!$A:$A,DATE(2026,5,23)),"—") | Y9: =IFERROR(SUMIFS(Data!$G:$G,Data!$B:$B,"อโศก",Data!$A:$A,DATE(2026,5,24)),"—") | Z9: =IFERROR(SUMIFS(Data!$G:$G,Data!$B:$B,"อโศก",Data!$A:$A,DATE(2026,5,25)),"—") | AA9: =IFERROR(SUMIFS(Data!$G:$G,Data!$B:$B,"อโศก",Data!$A:$A,DATE(2026,5,26)),"—") | AB9: =IFERROR(SUMIFS(Data!$G:$G,Data!$B:$B,"อโศก",Data!$A:$A,DATE(2026,5,27)),"—") | AC9: =IFERROR(SUMIFS(Data!$G:$G,Data!$B:$B,"อโศก",Data!$A:$A,DATE(2026,5,28)),"—") | AD9: =IFERROR(SUMIFS(Data!$G:$G,Data!$B:$B,"อโศก",Data!$A:$A,DATE(2026,5,29)),"—") | AE9: =IFERROR(SUMIFS(Data!$G:$G,Data!$B:$B,"อโศก",Data!$A:$A,DATE(2026,5,30)),"—") | AF9: =IFERROR(SUMIFS(Data!$G:$G,Data!$B:$B,"อโศก",Data!$A:$A,DATE(2026,5,31)),"—") | AG9: =IFERROR(SUM(B9:AF9),0) | AH9: =IFERROR(AG9/AG15,0)
A10: พระราม 3 | B10: =IFERROR(SUMIFS(Data!$G:$G,Data!$B:$B,"พระราม 3",Data!$A:$A,DATE(2026,5,1)),"—") | C10: =IFERROR(SUMIFS(Data!$G:$G,Data!$B:$B,"พระราม 3",Data!$A:$A,DATE(2026,5,2)),"—") | D10: =IFERROR(SUMIFS(Data!$G:$G,Data!$B:$B,"พระราม 3",Data!$A:$A,DATE(2026,5,3)),"—") | E10: =IFERROR(SUMIFS(Data!$G:$G,Data!$B:$B,"พระราม 3",Data!$A:$A,DATE(2026,5,4)),"—") | F10: =IFERROR(SUMIFS(Data!$G:$G,Data!$B:$B,"พระราม 3",Data!$A:$A,DATE(2026,5,5)),"—") | G10: =IFERROR(SUMIFS(Data!$G:$G,Data!$B:$B,"พระราม 3",Data!$A:$A,DATE(2026,5,6)),"—") | H10: =IFERROR(SUMIFS(Data!$G:$G,Data!$B:$B,"พระราม 3",Data!$A:$A,DATE(2026,5,7)),"—") | I10: =IFERROR(SUMIFS(Data!$G:$G,Data!$B:$B,"พระราม 3",Data!$A:$A,DATE(2026,5,8)),"—") | J10: =IFERROR(SUMIFS(Data!$G:$G,Data!$B:$B,"พระราม 3",Data!$A:$A,DATE(2026,5,9)),"—") | K10: =IFERROR(SUMIFS(Data!$G:$G,Data!$B:$B,"พระราม 3",Data!$A:$A,DATE(2026,5,10)),"—") | L10: =IFERROR(SUMIFS(Data!$G:$G,Data!$B:$B,"พระราม 3",Data!$A:$A,DATE(2026,5,11)),"—") | M10: =IFERROR(SUMIFS(Data!$G:$G,Data!$B:$B,"พระราม 3",Data!$A:$A,DATE(2026,5,12)),"—") | N10: =IFERROR(SUMIFS(Data!$G:$G,Data!$B:$B,"พระราม 3",Data!$A:$A,DATE(2026,5,13)),"—") | O10: =IFERROR(SUMIFS(Data!$G:$G,Data!$B:$B,"พระราม 3",Data!$A:$A,DATE(2026,5,14)),"—") | P10: =IFERROR(SUMIFS(Data!$G:$G,Data!$B:$B,"พระราม 3",Data!$A:$A,DATE(2026,5,15)),"—") | Q10: =IFERROR(SUMIFS(Data!$G:$G,Data!$B:$B,"พระราม 3",Data!$A:$A,DATE(2026,5,16)),"—") | R10: =IFERROR(SUMIFS(Data!$G:$G,Data!$B:$B,"พระราม 3",Data!$A:$A,DATE(2026,5,17)),"—") | S10: =IFERROR(SUMIFS(Data!$G:$G,Data!$B:$B,"พระราม 3",Data!$A:$A,DATE(2026,5,18)),"—") | T10: =IFERROR(SUMIFS(Data!$G:$G,Data!$B:$B,"พระราม 3",Data!$A:$A,DATE(2026,5,19)),"—") | U10: =IFERROR(SUMIFS(Data!$G:$G,Data!$B:$B,"พระราม 3",Data!$A:$A,DATE(2026,5,20)),"—") | V10: =IFERROR(SUMIFS(Data!$G:$G,Data!$B:$B,"พระราม 3",Data!$A:$A,DATE(2026,5,21)),"—") | W10: =IFERROR(SUMIFS(Data!$G:$G,Data!$B:$B,"พระราม 3",Data!$A:$A,DATE(2026,5,22)),"—") | X10: =IFERROR(SUMIFS(Data!$G:$G,Data!$B:$B,"พระราม 3",Data!$A:$A,DATE(2026,5,23)),"—") | Y10: =IFERROR(SUMIFS(Data!$G:$G,Data!$B:$B,"พระราม 3",Data!$A:$A,DATE(2026,5,24)),"—") | Z10: =IFERROR(SUMIFS(Data!$G:$G,Data!$B:$B,"พระราม 3",Data!$A:$A,DATE(2026,5,25)),"—") | AA10: =IFERROR(SUMIFS(Data!$G:$G,Data!$B:$B,"พระราม 3",Data!$A:$A,DATE(2026,5,26)),"—") | AB10: =IFERROR(SUMIFS(Data!$G:$G,Data!$B:$B,"พระราม 3",Data!$A:$A,DATE(2026,5,27)),"—") | AC10: =IFERROR(SUMIFS(Data!$G:$G,Data!$B:$B,"พระราม 3",Data!$A:$A,DATE(2026,5,28)),"—") | AD10: =IFERROR(SUMIFS(Data!$G:$G,Data!$B:$B,"พระราม 3",Data!$A:$A,DATE(2026,5,29)),"—") | AE10: =IFERROR(SUMIFS(Data!$G:$G,Data!$B:$B,"พระราม 3",Data!$A:$A,DATE(2026,5,30)),"—") | AF10: =IFERROR(SUMIFS(Data!$G:$G,Data!$B:$B,"พระราม 3",Data!$A:$A,DATE(2026,5,31)),"—") | AG10: =IFERROR(SUM(B10:AF10),0) | AH10: =IFERROR(AG10/AG15,0)
A11: แฟชั่น 3 | B11: =IFERROR(SUMIFS(Data!$G:$G,Data!$B:$B,"แฟชั่น 3",Data!$A:$A,DATE(2026,5,1)),"—") | C11: =IFERROR(SUMIFS(Data!$G:$G,Data!$B:$B,"แฟชั่น 3",Data!$A:$A,DATE(2026,5,2)),"—") | D11: =IFERROR(SUMIFS(Data!$G:$G,Data!$B:$B,"แฟชั่น 3",Data!$A:$A,DATE(2026,5,3)),"—") | E11: =IFERROR(SUMIFS(Data!$G:$G,Data!$B:$B,"แฟชั่น 3",Data!$A:$A,DATE(2026,5,4)),"—") | F11: =IFERROR(SUMIFS(Data!$G:$G,Data!$B:$B,"แฟชั่น 3",Data!$A:$A,DATE(2026,5,5)),"—") | G11: =IFERROR(SUMIFS(Data!$G:$G,Data!$B:$B,"แฟชั่น 3",Data!$A:$A,DATE(2026,5,6)),"—") | H11: =IFERROR(SUMIFS(Data!$G:$G,Data!$B:$B,"แฟชั่น 3",Data!$A:$A,DATE(2026,5,7)),"—") | I11: =IFERROR(SUMIFS(Data!$G:$G,Data!$B:$B,"แฟชั่น 3",Data!$A:$A,DATE(2026,5,8)),"—") | J11: =IFERROR(SUMIFS(Data!$G:$G,Data!$B:$B,"แฟชั่น 3",Data!$A:$A,DATE(2026,5,9)),"—") | K11: =IFERROR(SUMIFS(Data!$G:$G,Data!$B:$B,"แฟชั่น 3",Data!$A:$A,DATE(2026,5,10)),"—") | L11: =IFERROR(SUMIFS(Data!$G:$G,Data!$B:$B,"แฟชั่น 3",Data!$A:$A,DATE(2026,5,11)),"—") | M11: =IFERROR(SUMIFS(Data!$G:$G,Data!$B:$B,"แฟชั่น 3",Data!$A:$A,DATE(2026,5,12)),"—") | N11: =IFERROR(SUMIFS(Data!$G:$G,Data!$B:$B,"แฟชั่น 3",Data!$A:$A,DATE(2026,5,13)),"—") | O11: =IFERROR(SUMIFS(Data!$G:$G,Data!$B:$B,"แฟชั่น 3",Data!$A:$A,DATE(2026,5,14)),"—") | P11: =IFERROR(SUMIFS(Data!$G:$G,Data!$B:$B,"แฟชั่น 3",Data!$A:$A,DATE(2026,5,15)),"—") | Q11: =IFERROR(SUMIFS(Data!$G:$G,Data!$B:$B,"แฟชั่น 3",Data!$A:$A,DATE(2026,5,16)),"—") | R11: =IFERROR(SUMIFS(Data!$G:$G,Data!$B:$B,"แฟชั่น 3",Data!$A:$A,DATE(2026,5,17)),"—") | S11: =IFERROR(SUMIFS(Data!$G:$G,Data!$B:$B,"แฟชั่น 3",Data!$A:$A,DATE(2026,5,18)),"—") | T11: =IFERROR(SUMIFS(Data!$G:$G,Data!$B:$B,"แฟชั่น 3",Data!$A:$A,DATE(2026,5,19)),"—") | U11: =IFERROR(SUMIFS(Data!$G:$G,Data!$B:$B,"แฟชั่น 3",Data!$A:$A,DATE(2026,5,20)),"—") | V11: =IFERROR(SUMIFS(Data!$G:$G,Data!$B:$B,"แฟชั่น 3",Data!$A:$A,DATE(2026,5,21)),"—") | W11: =IFERROR(SUMIFS(Data!$G:$G,Data!$B:$B,"แฟชั่น 3",Data!$A:$A,DATE(2026,5,22)),"—") | X11: =IFERROR(SUMIFS(Data!$G:$G,Data!$B:$B,"แฟชั่น 3",Data!$A:$A,DATE(2026,5,23)),"—") | Y11: =IFERROR(SUMIFS(Data!$G:$G,Data!$B:$B,"แฟชั่น 3",Data!$A:$A,DATE(2026,5,24)),"—") | Z11: =IFERROR(SUMIFS(Data!$G:$G,Data!$B:$B,"แฟชั่น 3",Data!$A:$A,DATE(2026,5,25)),"—") | AA11: =IFERROR(SUMIFS(Data!$G:$G,Data!$B:$B,"แฟชั่น 3",Data!$A:$A,DATE(2026,5,26)),"—") | AB11: =IFERROR(SUMIFS(Data!$G:$G,Data!$B:$B,"แฟชั่น 3",Data!$A:$A,DATE(2026,5,27)),"—") | AC11: =IFERROR(SUMIFS(Data!$G:$G,Data!$B:$B,"แฟชั่น 3",Data!$A:$A,DATE(2026,5,28)),"—") | AD11: =IFERROR(SUMIFS(Data!$G:$G,Data!$B:$B,"แฟชั่น 3",Data!$A:$A,DATE(2026,5,29)),"—") | AE11: =IFERROR(SUMIFS(Data!$G:$G,Data!$B:$B,"แฟชั่น 3",Data!$A:$A,DATE(2026,5,30)),"—") | AF11: =IFERROR(SUMIFS(Data!$G:$G,Data!$B:$B,"แฟชั่น 3",Data!$A:$A,DATE(2026,5,31)),"—") | AG11: =IFERROR(SUM(B11:AF11),0) | AH11: =IFERROR(AG11/AG15,0)
A12: แฟชั่น B | B12: =IFERROR(SUMIFS(Data!$G:$G,Data!$B:$B,"แฟชั่น B",Data!$A:$A,DATE(2026,5,1)),"—") | C12: =IFERROR(SUMIFS(Data!$G:$G,Data!$B:$B,"แฟชั่น B",Data!$A:$A,DATE(2026,5,2)),"—") | D12: =IFERROR(SUMIFS(Data!$G:$G,Data!$B:$B,"แฟชั่น B",Data!$A:$A,DATE(2026,5,3)),"—") | E12: =IFERROR(SUMIFS(Data!$G:$G,Data!$B:$B,"แฟชั่น B",Data!$A:$A,DATE(2026,5,4)),"—") | F12: =IFERROR(SUMIFS(Data!$G:$G,Data!$B:$B,"แฟชั่น B",Data!$A:$A,DATE(2026,5,5)),"—") | G12: =IFERROR(SUMIFS(Data!$G:$G,Data!$B:$B,"แฟชั่น B",Data!$A:$A,DATE(2026,5,6)),"—") | H12: =IFERROR(SUMIFS(Data!$G:$G,Data!$B:$B,"แฟชั่น B",Data!$A:$A,DATE(2026,5,7)),"—") | I12: =IFERROR(SUMIFS(Data!$G:$G,Data!$B:$B,"แฟชั่น B",Data!$A:$A,DATE(2026,5,8)),"—") | J12: =IFERROR(SUMIFS(Data!$G:$G,Data!$B:$B,"แฟชั่น B",Data!$A:$A,DATE(2026,5,9)),"—") | K12: =IFERROR(SUMIFS(Data!$G:$G,Data!$B:$B,"แฟชั่น B",Data!$A:$A,DATE(2026,5,10)),"—") | L12: =IFERROR(SUMIFS(Data!$G:$G,Data!$B:$B,"แฟชั่น B",Data!$A:$A,DATE(2026,5,11)),"—") | M12: =IFERROR(SUMIFS(Data!$G:$G,Data!$B:$B,"แฟชั่น B",Data!$A:$A,DATE(2026,5,12)),"—") | N12: =IFERROR(SUMIFS(Data!$G:$G,Data!$B:$B,"แฟชั่น B",Data!$A:$A,DATE(2026,5,13)),"—") | O12: =IFERROR(SUMIFS(Data!$G:$G,Data!$B:$B,"แฟชั่น B",Data!$A:$A,DATE(2026,5,14)),"—") | P12: =IFERROR(SUMIFS(Data!$G:$G,Data!$B:$B,"แฟชั่น B",Data!$A:$A,DATE(2026,5,15)),"—") | Q12: =IFERROR(SUMIFS(Data!$G:$G,Data!$B:$B,"แฟชั่น B",Data!$A:$A,DATE(2026,5,16)),"—") | R12: =IFERROR(SUMIFS(Data!$G:$G,Data!$B:$B,"แฟชั่น B",Data!$A:$A,DATE(2026,5,17)),"—") | S12: =IFERROR(SUMIFS(Data!$G:$G,Data!$B:$B,"แฟชั่น B",Data!$A:$A,DATE(2026,5,18)),"—") | T12: =IFERROR(SUMIFS(Data!$G:$G,Data!$B:$B,"แฟชั่น B",Data!$A:$A,DATE(2026,5,19)),"—") | U12: =IFERROR(SUMIFS(Data!$G:$G,Data!$B:$B,"แฟชั่น B",Data!$A:$A,DATE(2026,5,20)),"—") | V12: =IFERROR(SUMIFS(Data!$G:$G,Data!$B:$B,"แฟชั่น B",Data!$A:$A,DATE(2026,5,21)),"—") | W12: =IFERROR(SUMIFS(Data!$G:$G,Data!$B:$B,"แฟชั่น B",Data!$A:$A,DATE(2026,5,22)),"—") | X12: =IFERROR(SUMIFS(Data!$G:$G,Data!$B:$B,"แฟชั่น B",Data!$A:$A,DATE(2026,5,23)),"—") | Y12: =IFERROR(SUMIFS(Data!$G:$G,Data!$B:$B,"แฟชั่น B",Data!$A:$A,DATE(2026,5,24)),"—") | Z12: =IFERROR(SUMIFS(Data!$G:$G,Data!$B:$B,"แฟชั่น B",Data!$A:$A,DATE(2026,5,25)),"—") | AA12: =IFERROR(SUMIFS(Data!$G:$G,Data!$B:$B,"แฟชั่น B",Data!$A:$A,DATE(2026,5,26)),"—") | AB12: =IFERROR(SUMIFS(Data!$G:$G,Data!$B:$B,"แฟชั่น B",Data!$A:$A,DATE(2026,5,27)),"—") | AC12: =IFERROR(SUMIFS(Data!$G:$G,Data!$B:$B,"แฟชั่น B",Data!$A:$A,DATE(2026,5,28)),"—") | AD12: =IFERROR(SUMIFS(Data!$G:$G,Data!$B:$B,"แฟชั่น B",Data!$A:$A,DATE(2026,5,29)),"—") | AE12: =IFERROR(SUMIFS(Data!$G:$G,Data!$B:$B,"แฟชั่น B",Data!$A:$A,DATE(2026,5,30)),"—") | AF12: =IFERROR(SUMIFS(Data!$G:$G,Data!$B:$B,"แฟชั่น B",Data!$A:$A,DATE(2026,5,31)),"—") | AG12: =IFERROR(SUM(B12:AF12),0) | AH12: =IFERROR(AG12/AG15,0)
A13: เอสพลานาด | B13: =IFERROR(SUMIFS(Data!$G:$G,Data!$B:$B,"เอสพลานาด",Data!$A:$A,DATE(2026,5,1)),"—") | C13: =IFERROR(SUMIFS(Data!$G:$G,Data!$B:$B,"เอสพลานาด",Data!$A:$A,DATE(2026,5,2)),"—") | D13: =IFERROR(SUMIFS(Data!$G:$G,Data!$B:$B,"เอสพลานาด",Data!$A:$A,DATE(2026,5,3)),"—") | E13: =IFERROR(SUMIFS(Data!$G:$G,Data!$B:$B,"เอสพลานาด",Data!$A:$A,DATE(2026,5,4)),"—") | F13: =IFERROR(SUMIFS(Data!$G:$G,Data!$B:$B,"เอสพลานาด",Data!$A:$A,DATE(2026,5,5)),"—") | G13: =IFERROR(SUMIFS(Data!$G:$G,Data!$B:$B,"เอสพลานาด",Data!$A:$A,DATE(2026,5,6)),"—") | H13: =IFERROR(SUMIFS(Data!$G:$G,Data!$B:$B,"เอสพลานาด",Data!$A:$A,DATE(2026,5,7)),"—") | I13: =IFERROR(SUMIFS(Data!$G:$G,Data!$B:$B,"เอสพลานาด",Data!$A:$A,DATE(2026,5,8)),"—") | J13: =IFERROR(SUMIFS(Data!$G:$G,Data!$B:$B,"เอสพลานาด",Data!$A:$A,DATE(2026,5,9)),"—") | K13: =IFERROR(SUMIFS(Data!$G:$G,Data!$B:$B,"เอสพลานาด",Data!$A:$A,DATE(2026,5,10)),"—") | L13: =IFERROR(SUMIFS(Data!$G:$G,Data!$B:$B,"เอสพลานาด",Data!$A:$A,DATE(2026,5,11)),"—") | M13: =IFERROR(SUMIFS(Data!$G:$G,Data!$B:$B,"เอสพลานาด",Data!$A:$A,DATE(2026,5,12)),"—") | N13: =IFERROR(SUMIFS(Data!$G:$G,Data!$B:$B,"เอสพลานาด",Data!$A:$A,DATE(2026,5,13)),"—") | O13: =IFERROR(SUMIFS(Data!$G:$G,Data!$B:$B,"เอสพลานาด",Data!$A:$A,DATE(2026,5,14)),"—") | P13: =IFERROR(SUMIFS(Data!$G:$G,Data!$B:$B,"เอสพลานาด",Data!$A:$A,DATE(2026,5,15)),"—") | Q13: =IFERROR(SUMIFS(Data!$G:$G,Data!$B:$B,"เอสพลานาด",Data!$A:$A,DATE(2026,5,16)),"—") | R13: =IFERROR(SUMIFS(Data!$G:$G,Data!$B:$B,"เอสพลานาด",Data!$A:$A,DATE(2026,5,17)),"—") | S13: =IFERROR(SUMIFS(Data!$G:$G,Data!$B:$B,"เอสพลานาด",Data!$A:$A,DATE(2026,5,18)),"—") | T13: =IFERROR(SUMIFS(Data!$G:$G,Data!$B:$B,"เอสพลานาด",Data!$A:$A,DATE(2026,5,19)),"—") | U13: =IFERROR(SUMIFS(Data!$G:$G,Data!$B:$B,"เอสพลานาด",Data!$A:$A,DATE(2026,5,20)),"—") | V13: =IFERROR(SUMIFS(Data!$G:$G,Data!$B:$B,"เอสพลานาด",Data!$A:$A,DATE(2026,5,21)),"—") | W13: =IFERROR(SUMIFS(Data!$G:$G,Data!$B:$B,"เอสพลานาด",Data!$A:$A,DATE(2026,5,22)),"—") | X13: =IFERROR(SUMIFS(Data!$G:$G,Data!$B:$B,"เอสพลานาด",Data!$A:$A,DATE(2026,5,23)),"—") | Y13: =IFERROR(SUMIFS(Data!$G:$G,Data!$B:$B,"เอสพลานาด",Data!$A:$A,DATE(2026,5,24)),"—") | Z13: =IFERROR(SUMIFS(Data!$G:$G,Data!$B:$B,"เอสพลานาด",Data!$A:$A,DATE(2026,5,25)),"—") | AA13: =IFERROR(SUMIFS(Data!$G:$G,Data!$B:$B,"เอสพลานาด",Data!$A:$A,DATE(2026,5,26)),"—") | AB13: =IFERROR(SUMIFS(Data!$G:$G,Data!$B:$B,"เอสพลานาด",Data!$A:$A,DATE(2026,5,27)),"—") | AC13: =IFERROR(SUMIFS(Data!$G:$G,Data!$B:$B,"เอสพลานาด",Data!$A:$A,DATE(2026,5,28)),"—") | AD13: =IFERROR(SUMIFS(Data!$G:$G,Data!$B:$B,"เอสพลานาด",Data!$A:$A,DATE(2026,5,29)),"—") | AE13: =IFERROR(SUMIFS(Data!$G:$G,Data!$B:$B,"เอสพลานาด",Data!$A:$A,DATE(2026,5,30)),"—") | AF13: =IFERROR(SUMIFS(Data!$G:$G,Data!$B:$B,"เอสพลานาด",Data!$A:$A,DATE(2026,5,31)),"—") | AG13: =IFERROR(SUM(B13:AF13),0) | AH13: =IFERROR(AG13/AG15,0)
A14: ขายเงินสด | B14: =IFERROR(SUMIFS(Data!$G:$G,Data!$B:$B,"ขายเงินสด",Data!$A:$A,DATE(2026,5,1)),"—") | C14: =IFERROR(SUMIFS(Data!$G:$G,Data!$B:$B,"ขายเงินสด",Data!$A:$A,DATE(2026,5,2)),"—") | D14: =IFERROR(SUMIFS(Data!$G:$G,Data!$B:$B,"ขายเงินสด",Data!$A:$A,DATE(2026,5,3)),"—") | E14: =IFERROR(SUMIFS(Data!$G:$G,Data!$B:$B,"ขายเงินสด",Data!$A:$A,DATE(2026,5,4)),"—") | F14: =IFERROR(SUMIFS(Data!$G:$G,Data!$B:$B,"ขายเงินสด",Data!$A:$A,DATE(2026,5,5)),"—") | G14: =IFERROR(SUMIFS(Data!$G:$G,Data!$B:$B,"ขายเงินสด",Data!$A:$A,DATE(2026,5,6)),"—") | H14: =IFERROR(SUMIFS(Data!$G:$G,Data!$B:$B,"ขายเงินสด",Data!$A:$A,DATE(2026,5,7)),"—") | I14: =IFERROR(SUMIFS(Data!$G:$G,Data!$B:$B,"ขายเงินสด",Data!$A:$A,DATE(2026,5,8)),"—") | J14: =IFERROR(SUMIFS(Data!$G:$G,Data!$B:$B,"ขายเงินสด",Data!$A:$A,DATE(2026,5,9)),"—") | K14: =IFERROR(SUMIFS(Data!$G:$G,Data!$B:$B,"ขายเงินสด",Data!$A:$A,DATE(2026,5,10)),"—") | L14: =IFERROR(SUMIFS(Data!$G:$G,Data!$B:$B,"ขายเงินสด",Data!$A:$A,DATE(2026,5,11)),"—") | M14: =IFERROR(SUMIFS(Data!$G:$G,Data!$B:$B,"ขายเงินสด",Data!$A:$A,DATE(2026,5,12)),"—") | N14: =IFERROR(SUMIFS(Data!$G:$G,Data!$B:$B,"ขายเงินสด",Data!$A:$A,DATE(2026,5,13)),"—") | O14: =IFERROR(SUMIFS(Data!$G:$G,Data!$B:$B,"ขายเงินสด",Data!$A:$A,DATE(2026,5,14)),"—") | P14: =IFERROR(SUMIFS(Data!$G:$G,Data!$B:$B,"ขายเงินสด",Data!$A:$A,DATE(2026,5,15)),"—") | Q14: =IFERROR(SUMIFS(Data!$G:$G,Data!$B:$B,"ขายเงินสด",Data!$A:$A,DATE(2026,5,16)),"—") | R14: =IFERROR(SUMIFS(Data!$G:$G,Data!$B:$B,"ขายเงินสด",Data!$A:$A,DATE(2026,5,17)),"—") | S14: =IFERROR(SUMIFS(Data!$G:$G,Data!$B:$B,"ขายเงินสด",Data!$A:$A,DATE(2026,5,18)),"—") | T14: =IFERROR(SUMIFS(Data!$G:$G,Data!$B:$B,"ขายเงินสด",Data!$A:$A,DATE(2026,5,19)),"—") | U14: =IFERROR(SUMIFS(Data!$G:$G,Data!$B:$B,"ขายเงินสด",Data!$A:$A,DATE(2026,5,20)),"—") | V14: =IFERROR(SUMIFS(Data!$G:$G,Data!$B:$B,"ขายเงินสด",Data!$A:$A,DATE(2026,5,21)),"—") | W14: =IFERROR(SUMIFS(Data!$G:$G,Data!$B:$B,"ขายเงินสด",Data!$A:$A,DATE(2026,5,22)),"—") | X14: =IFERROR(SUMIFS(Data!$G:$G,Data!$B:$B,"ขายเงินสด",Data!$A:$A,DATE(2026,5,23)),"—") | Y14: =IFERROR(SUMIFS(Data!$G:$G,Data!$B:$B,"ขายเงินสด",Data!$A:$A,DATE(2026,5,24)),"—") | Z14: =IFERROR(SUMIFS(Data!$G:$G,Data!$B:$B,"ขายเงินสด",Data!$A:$A,DATE(2026,5,25)),"—") | AA14: =IFERROR(SUMIFS(Data!$G:$G,Data!$B:$B,"ขายเงินสด",Data!$A:$A,DATE(2026,5,26)),"—") | AB14: =IFERROR(SUMIFS(Data!$G:$G,Data!$B:$B,"ขายเงินสด",Data!$A:$A,DATE(2026,5,27)),"—") | AC14: =IFERROR(SUMIFS(Data!$G:$G,Data!$B:$B,"ขายเงินสด",Data!$A:$A,DATE(2026,5,28)),"—") | AD14: =IFERROR(SUMIFS(Data!$G:$G,Data!$B:$B,"ขายเงินสด",Data!$A:$A,DATE(2026,5,29)),"—") | AE14: =IFERROR(SUMIFS(Data!$G:$G,Data!$B:$B,"ขายเงินสด",Data!$A:$A,DATE(2026,5,30)),"—") | AF14: =IFERROR(SUMIFS(Data!$G:$G,Data!$B:$B,"ขายเงินสด",Data!$A:$A,DATE(2026,5,31)),"—") | AG14: =IFERROR(SUM(B14:AF14),0) | AH14: =IFERROR(AG14/AG15,0)
A15: รวมทุกสาขา | B15: =IFERROR(SUM(B9:B14),0) | C15: =IFERROR(SUM(C9:C14),0) | D15: =IFERROR(SUM(D9:D14),0) | E15: =IFERROR(SUM(E9:E14),0) | F15: =IFERROR(SUM(F9:F14),0) | G15: =IFERROR(SUM(G9:G14),0) | H15: =IFERROR(SUM(H9:H14),0) | I15: =IFERROR(SUM(I9:I14),0) | ... AG15: =IFERROR(SUM(AG9:AG14),0) | AH15: 100.0%
A17: 💰 ยอดรับเงิน (งวด 1–15 / 16–31)
A18: สาขา | B18: ยอดขาย 1-15 | C18: ยอดรับ 1-15 | D18: ยอดขาย 16-31 | E18: ยอดรับ 16-31 | F18: ยอดขายรวม | G18: ยอดรับรวม
A19: อโศก | B19: =IFERROR(SUMIFS(Data!$G:$G,Data!$B:$B,"อโศก",Data!$A:$A,">="&DATE(2026,5,1),Data!$A:$A,"<="&DATE(2026,5,15)),0) | C19: =B19*0.9803738318 | D19: =IFERROR(SUMIFS(Data!$G:$G,Data!$B:$B,"อโศก",Data!$A:$A,">="&DATE(2026,5,16),Data!$A:$A,"<="&DATE(2026,5,31)),0) | E19: =D19*0.9803738318 | F19: =B19+D19 | G19: =C19+E19
A20: พระราม 3 | B20: =IFERROR(SUMIFS(Data!$G:$G,Data!$B:$B,"พระราม 3",Data!$A:$A,">="&DATE(2026,5,1),Data!$A:$A,"<="&DATE(2026,5,15)),0) | C20: =B20*0.9803738318 | D20: =IFERROR(SUMIFS(Data!$G:$G,Data!$B:$B,"พระราม 3",Data!$A:$A,">="&DATE(2026,5,16),Data!$A:$A,"<="&DATE(2026,5,31)),0) | E20: =D20*0.9803738318 | F20: =B20+D20 | G20: =C20+E20
A21: แฟชั่น 3 | B21: =IFERROR(SUMIFS(Data!$G:$G,Data!$B:$B,"แฟชั่น 3",Data!$A:$A,">="&DATE(2026,5,1),Data!$A:$A,"<="&DATE(2026,5,15)),0) | C21: =B21*0.7 | D21: =IFERROR(SUMIFS(Data!$G:$G,Data!$B:$B,"แฟชั่น 3",Data!$A:$A,">="&DATE(2026,5,16),Data!$A:$A,"<="&DATE(2026,5,31)),0) | E21: =D21*0.7 | F21: =B21+D21 | G21: =C21+E21
A22: แฟชั่น B | B22: =IFERROR(SUMIFS(Data!$G:$G,Data!$B:$B,"แฟชั่น B",Data!$A:$A,">="&DATE(2026,5,1),Data!$A:$A,"<="&DATE(2026,5,15)),0) | C22: =B22*0.7 | D22: =IFERROR(SUMIFS(Data!$G:$G,Data!$B:$B,"แฟชั่น B",Data!$A:$A,">="&DATE(2026,5,16),Data!$A:$A,"<="&DATE(2026,5,31)),0) | E22: =D22*0.7 | F22: =B22+D22 | G22: =C22+E22
A23: เอสพลานาด | B23: =IFERROR(SUMIFS(Data!$G:$G,Data!$B:$B,"เอสพลานาด",Data!$A:$A,">="&DATE(2026,5,1),Data!$A:$A,"<="&DATE(2026,5,15)),0) | C23: =B23*0.7111 | D23: =IFERROR(SUMIFS(Data!$G:$G,Data!$B:$B,"เอสพลานาด",Data!$A:$A,">="&DATE(2026,5,16),Data!$A:$A,"<="&DATE(2026,5,31)),0) | E23: =D23*0.7111 | F23: =B23+D23 | G23: =C23+E23
A24: ขายเงินสด | B24: =IFERROR(SUMIFS(Data!$G:$G,Data!$B:$B,"ขายเงินสด",Data!$A:$A,">="&DATE(2026,5,1),Data!$A:$A,"<="&DATE(2026,5,15)),0) | C24: =B24*0.9345794393 | D24: =IFERROR(SUMIFS(Data!$G:$G,Data!$B:$B,"ขายเงินสด",Data!$A:$A,">="&DATE(2026,5,16),Data!$A:$A,"<="&DATE(2026,5,31)),0) | E24: =D24*0.9345794393 | F24: =B24+D24 | G24: =C24+E24
A25: รวมทุกสาขา | B25: =IFERROR(SUM(B19:B24),0) | C25: =IFERROR(SUM(C19:C24),0) | D25: =IFERROR(SUM(D19:D24),0) | E25: =IFERROR(SUM(E19:E24),0) | F25: =IFERROR(SUM(F19:F24),0) | G25: =IFERROR(SUM(G19:G24),0)

Sheet Data
A1: date | B1: branch | C1: item_code | D1: item_name | E1: price | F1: qty | G1: amount
A2: YYYY-MM-DD | B2: ชื่อสาขาไทย | C2: รหัสสินค้า | D2: ชื่อเมนู | E2: ราคาต่อจาน | F2: จำนวนจาน | G2: ยอดรวม
A3: ← ตัวอย่าง (Python จะเขียนทับ) | B3: อโศก | C3: ITEM0942 | D3: ข้าวมันไก่ต้ม | E3: 35 | F3: 168 | G3: 5880

Sheet Item Master
A1: Item Master — อ้างอิงจาก item_master.json (อย่าแก้ไข อัปเดตผ่าน Python)
A2: สาขา | B2: Item_Code | C2: ชื่อเมนู | D2: ราคา
A3: อโศก | B3: ITEM0029 | C3: 29 ค่าอาหาร (10 บาท) | D3: 10
A4: อโศก | B4: ITEM0042 | C4: 12 กลับบ้านเพิ่ม | D4: 5
A5: อโศก | B5: ITEM0179 | C5: 22 ค่าอาหาร (15 บาท) | D5: 15
A6: อโศก | B6: ITEM0180 | C6: 23 ค่าอาหาร (20 บาท) | D6: 20
A7: อโศก | B7: ITEM0181 | C7: 24 ค่าอาหาร (30 บาท) | D7: 30
A8: อโศก | B8: ITEM0941 | C8: ข้าวมันไก่สิงคโปร์ | D8: 57
A9: อโศก | B9: ITEM0942 | C9: ข้าวมันไก่ต้ม | D9: 35
A10: อโศก | B10: ITEM0943 | C10: ข้าวมันไก่ทอด | D10: 35
A11: อโศก | B11: ITEM0944 | C11: ข้าวมันไก่ผสม | D11: 40
A12: อโศก | B12: ITEM0945 | C12: ข้าวยำไก่แซ่บ | D12: 38
A13: อโศก | B13: ITEM0946 | C13: ยำแซ่บไก่ฉีก | D13: 32
A14: อโศก | B14: ITEM0947 | C14: ชุดเซต ข้าวมันไก่ต้ม | D14: 100
... A65: เอสพลานาด | B65: FG-ES-RAT-15 | C65: ข้าวมันไก่สิงคโปร์ | D65: 75

Sheet อโศก
A1: สาขา อโศก — ยอดขายรายเมนู พฤษภาคม 2569
A3: Item_Code | B3: ชื่อเมนู | C3: ศ 1/5 | D3: ส 2/5 | E3: อา 3/5 | F3: จ 4/5 | G3: อ 5/5 | H3: พ 6/5 | I3: พฤ 7/5 | J3: ศ 8/5 | K3: ส 9/5 | L3: อา 10/5 | M3: จ 11/5 | N3: อ 12/5 | O3: พ 13/5 | P3: พฤ 14/5 | Q3: ศ 15/5 | R3: ส 16/5 | S3: อา 17/5 | T3: จ 18/5 | U3: อ 19/5 | V3: พ 20/5 | W3: พฤ 21/5 | X3: ศ 22/5 | Y3: ส 23/5 | Z3: อา 24/5 | AA3: จ 25/5 | AB3: อ 26/5 | AC3: พ 27/5 | AD3: พฤ 28/5 | AE3: ศ 29/5 | AF3: ส 30/5 | AG3: อา 31/5 | AH3: รวม (จาน) | AI3: รวม (฿) | AJ3: % | AK3: ยอดขาย 1-15 | AL3: ยอดขาย 16-31 | AM3: ยอดรับ 1-15 | AN3: ยอดรับ 16-31
A4: ITEM0029 | B4: 29 ค่าอาหาร (10 บาท) | C4: =IFERROR(SUMIFS(Data!$F:$F,Data!$B:$B,"อโศก",Data!$C:$C,"ITEM0029",Data!$A:$A,DATE(2026,5,1)),"") | D4: =IFERROR(SUMIFS(Data!$F:$F,Data!$B:$B,"อโศก",Data!$C:$C,"ITEM0029",Data!$A:$A,DATE(2026,5,2)),"") | E4: =IFERROR(SUMIFS(Data!$F:$F,Data!$B:$B,"อโศก",Data!$C:$C,"ITEM0029",Data!$A:$A,DATE(2026,5,3)),"") | F4: =IFERROR(SUMIFS(Data!$F:$F,Data!$B:$B,"อโศก",Data!$C:$C,"ITEM0029",Data!$A:$A,DATE(2026,5,4)),"") | G4: =IFERROR(SUMIFS(Data!$F:$F,Data!$B:$B,"อโศก",Data!$C:$C,"ITEM0029",Data!$A:$A,DATE(2026,5,5)),"") | H4: =IFERROR(SUMIFS(Data!$F:$F,Data!$B:$B,"อโศก",Data!$C:$C,"ITEM0029",Data!$A:$A,DATE(2026,5,6)),"") | I4: =IFERROR(SUMIFS(Data!$F:$F,Data!$B:$B,"อโศก",Data!$C:$C,"ITEM0029",Data!$A:$A,DATE(2026,5,7)),"") | J4: =IFERROR(SUMIFS(Data!$F:$F,Data!$B:$B,"อโศก",Data!$C:$C,"ITEM0029",Data!$A:$A,DATE(2026,5,8)),"") | K4: =IFERROR(SUMIFS(Data!$F:$F,Data!$B:$B,"อโศก",Data!$C:$C,"ITEM0029",Data!$A:$A,DATE(2026,5,9)),"") | L4: =IFERROR(SUMIFS(Data!$F:$F,Data!$B:$B,"อโศก",Data!$C:$C,"ITEM0029",Data!$A:$A,DATE(2026,5,10)),"") | M4: =IFERROR(SUMIFS(Data!$F:$F,Data!$B:$B,"อโศก",Data!$C:$C,"ITEM0029",Data!$A:$A,DATE(2026,5,11)),"") | N4: =IFERROR(SUMIFS(Data!$F:$F,Data!$B:$B,"อโศก",Data!$C:$C,"ITEM0029",Data!$A:$A,DATE(2026,5,12)),"") | O4: =IFERROR(SUMIFS(Data!$F:$F,Data!$B:$B,"อโศก",Data!$C:$C,"ITEM0029",Data!$A:$A,DATE(2026,5,13)),"") | P4: =IFERROR(SUMIFS(Data!$F:$F,Data!$B:$B,"อโศก",Data!$C:$C,"ITEM0029",Data!$A:$A,DATE(2026,5,14)),"") | Q4: =IFERROR(SUMIFS(Data!$F:$F,Data!$B:$B,"อโศก",Data!$C:$C,"ITEM0029",Data!$A:$A,DATE(2026,5,15)),"") | R4: =IFERROR(SUMIFS(Data!$F:$F,Data!$B:$B,"อโศก",Data!$C:$C,"ITEM0029",Data!$A:$A,DATE(2026,5,16)),"") | S4: =IFERROR(SUMIFS(Data!$F:$F,Data!$B:$B,"อโศก",Data!$C:$C,"ITEM0029",Data!$A:$A,DATE(2026,5,17)),"") | T4: =IFERROR(SUMIFS(Data!$F:$F,Data!$B:$B,"อโศก",Data!$C:$C,"ITEM0029",Data!$A:$A,DATE(2026,5,18)),"") | U4: =IFERROR(SUMIFS(Data!$F:$F,Data!$B:$B,"อโศก",Data!$C:$C,"ITEM0029",Data!$A:$A,DATE(2026,5,19)),"") | V4: =IFERROR(SUMIFS(Data!$F:$F,Data!$B:$B,"อโศก",Data!$C:$C,"ITEM0029",Data!$A:$A,DATE(2026,5,20)),"") | W4: =IFERROR(SUMIFS(Data!$F:$F,Data!$B:$B,"อโศก",Data!$C:$C,"ITEM0029",Data!$A:$A,DATE(2026,5,21)),"") | X4: =IFERROR(SUMIFS(Data!$F:$F,Data!$B:$B,"อโศก",Data!$C:$C,"ITEM0029",Data!$A:$A,DATE(2026,5,22)),"") | Y4: =IFERROR(SUMIFS(Data!$F:$F,Data!$B:$B,"อโศก",Data!$C:$C,"ITEM0029",Data!$A:$A,DATE(2026,5,23)),"") | Z4: =IFERROR(SUMIFS(Data!$F:$F,Data!$B:$B,"อโศก",Data!$C:$C,"ITEM0029",Data!$A:$A,DATE(2026,5,24)),"") | AA4: =IFERROR(SUMIFS(Data!$F:$F,Data!$B:$B,"อโศก",Data!$C:$C,"ITEM0029",Data!$A:$A,DATE(2026,5,25)),"") | AB4: =IFERROR(SUMIFS(Data!$F:$F,Data!$B:$B,"อโศก",Data!$C:$C,"ITEM0029",Data!$A:$A,DATE(2026,5,26)),"") | AC4: =IFERROR(SUMIFS(Data!$F:$F,Data!$B:$B,"อโศก",Data!$C:$C,"ITEM0029",Data!$A:$A,DATE(2026,5,27)),"") | AD4: =IFERROR(SUMIFS(Data!$F:$F,Data!$B:$B,"อโศก",Data!$C:$C,"ITEM0029",Data!$A:$A,DATE(2026,5,28)),"") | AE4: =IFERROR(SUMIFS(Data!$F:$F,Data!$B:$B,"อโศก",Data!$C:$C,"ITEM0029",Data!$A:$A,DATE(2026,5,29)),"") | AF4: =IFERROR(SUMIFS(Data!$F:$F,Data!$B:$B,"อโศก",Data!$C:$C,"ITEM0029",Data!$A:$A,DATE(2026,5,30)),"") | AG4: =IFERROR(SUMIFS(Data!$F:$F,Data!$B:$B,"อโศก",Data!$C:$C,"ITEM0029",Data!$A:$A,DATE(2026,5,31)),"") | AH4: =IFERROR(SUM(C4:AG4),0) | AI4: =AH4*10 | AJ4: =IFERROR(AI4/AI20,0)
A5: ITEM0042 | B5: 12 กลับบ้านเพิ่ม | C5: =IFERROR(SUMIFS(Data!$F:$F,Data!$B:$B,"อโศก",Data!$C:$C,"ITEM0042",Data!$A:$A,DATE(2026,5,1)),"") | D5: =IFERROR(SUMIFS(Data!$F:$F,Data!$B:$B,"อโศก",Data!$C:$C,"ITEM0042",Data!$A:$A,DATE(2026,5,2)),"") | E5: =IFERROR(SUMIFS(Data!$F:$F,Data!$B:$B,"อโศก",Data!$C:$C,"ITEM0042",Data!$A:$A,DATE(2026,5,3)),"") | F5: =IFERROR(SUMIFS(Data!$F:$F,Data!$B:$B,"อโศก",Data!$C:$C,"ITEM0042",Data!$A:$A,DATE(2026,5,4)),"") | G5: =IFERROR(SUMIFS(Data!$F:$F,Data!$B:$B,"อโศก",Data!$C:$C,"ITEM0042",Data!$A:$A,DATE(2026,5,5)),"") | H5: =IFERROR(SUMIFS(Data!$F:$F,Data!$B:$B,"อโศก",Data!$C:$C,"ITEM0042",Data!$A:$A,DATE(2026,5,6)),"") | I5: =IFERROR(SUMIFS(Data!$F:$F,Data!$B:$B,"อโศก",Data!$C:$C,"ITEM0042",Data!$A:$A,DATE(2026,5,7)),"") | J5: =IFERROR(SUMIFS(Data!$F:$F,Data!$B:$B,"อโศก",Data!$C:$C,"ITEM0042",Data!$A:$A,DATE(2026,5,8)),"") | K5: =IFERROR(SUMIFS(Data!$F:$F,Data!$B:$B,"อโศก",Data!$C:$C,"ITEM0042",Data!$A:$A,DATE(2026,5,9)),"") | L5: =IFERROR(SUMIFS(Data!$F:$F,Data!$B:$B,"อโศก",Data!$C:$C,"ITEM0042",Data!$A:$A,DATE(2026,5,10)),"") | M5: =IFERROR(SUMIFS(Data!$F:$F,Data!$B:$B,"อโศก",Data!$C:$C,"ITEM0042",Data!$A:$A,DATE(2026,5,11)),"") | N5: =IFERROR(SUMIFS(Data!$F:$F,Data!$B:$B,"อโศก",Data!$C:$C,"ITEM0042",Data!$A:$A,DATE(2026,5,12)),"") | O5: =IFERROR(SUMIFS(Data!$F:$F,Data!$B:$B,"อโศก",Data!$C:$C,"ITEM0042",Data!$A:$A,DATE(2026,5,13)),"") | P5: =IFERROR(SUMIFS(Data!$F:$F,Data!$B:$B,"อโศก",Data!$C:$C,"ITEM0042",Data!$A:$A,DATE(2026,5,14)),"") | Q5: =IFERROR(SUMIFS(Data!$F:$F,Data!$B:$B,"อโศก",Data!$C:$C,"ITEM0042",Data!$A:$A,DATE(2026,5,15)),"") | R5: =IFERROR(SUMIFS(Data!$F:$F,Data!$B:$B,"อโศก",Data!$C:$C,"ITEM0042",Data!$A:$A,DATE(2026,5,16)),"") | S5: =IFERROR(SUMIFS(Data!$F:$F,Data!$B:$B,"อโศก",Data!$C:$C,"ITEM0042",Data!$A:$A,DATE(2026,5,17)),"") | T5: =IFERROR(SUMIFS(Data!$F:$F,Data!$B:$B,"อโศก",Data!$C:$C,"ITEM0042",Data!$A:$A,DATE(2026,5,18)),"") | U5: =IFERROR(SUMIFS(Data!$F:$F,Data!$B:$B,"อโศก",Data!$C:$C,"ITEM0042",Data!$A:$A,DATE(2026,5,19)),"") | V5: =IFERROR(SUMIFS(Data!$F:$F,Data!$B:$B,"อโศก",Data!$C:$C,"ITEM0042",Data!$A:$A,DATE(2026,5,20)),"") | W5: =IFERROR(SUMIFS(Data!$F:$F,Data!$B:$B,"อโศก",Data!$C:$C,"ITEM0042",Data!$A:$A,DATE(2026,5,21)),"") | X5: =IFERROR(SUMIFS(Data!$F:$F,Data!$B:$B,"อโศก",Data!$C:$C,"ITEM0042",Data!$A:$A,DATE(2026,5,22)),"") | Y5: =IFERROR(SUMIFS(Data!$F:$F,Data!$B:$B,"อโศก",Data!$C:$C,"ITEM0042",Data!$A:$A,DATE(2026,5,23)),"") | Z5: =IFERROR(SUMIFS(Data!$F:$F,Data!$B:$B,"อโศก",Data!$C:$C,"ITEM0042",Data!$A:$A,DATE(2026,5,24)),"") | AA5: =IFERROR(SUMIFS(Data!$F:$F,Data!$B:$B,"อโศก",Data!$C:$C,"ITEM0042",Data!$A:$A,DATE(2026,5,25)),"") | AB5: =IFERROR(SUMIFS(Data!$F:$F,Data!$B:$B,"อโศก",Data!$C:$C,"ITEM0042",Data!$A:$A,DATE(2026,5,26)),"") | AC5: =IFERROR(SUMIFS(Data!$F:$F,Data!$B:$B,"อโศก",Data!$C:$C,"ITEM0042",Data!$A:$A,DATE(2026,5,27)),"") | AD5: =IFERROR(SUMIFS(Data!$F:$F,Data!$B:$B,"อโศก",Data!$C:$C,"ITEM0042",Data!$A:$A,DATE(2026,5,28)),"") | AE5: =IFERROR(SUMIFS(Data!$F:$F,Data!$B:$B,"อโศก",Data!$C:$C,"ITEM0042",Data!$A:$A,DATE(2026,5,29)),"") | AF5: =IFERROR(SUMIFS(Data!$F:$F,Data!$B:$B,"อโศก",Data!$C:$C,"ITEM0042",Data!$A:$A,DATE(2026,5,30)),"") | AG5: =IFERROR(SUMIFS(Data!$F:$F,Data!$B:$B,"อโศก",Data!$C:$C,"ITEM0042",Data!$A:$A,DATE(2026,5,31)),"") | AH5: =IFERROR(SUM(C5:AG5),0) | AI5: =AH5*5 | AJ5: =IFERROR(AI5/AI20,0)
A6: ITEM0179 | B6: 22 ค่าอาหาร (15 บาท) | C6: =IFERROR(SUMIFS(Data!$F:$F,Data!$B:$B,"อโศก",Data!$C:$C,"ITEM0179",Data!$A:$A,DATE(2026,5,1)),"") | D6: =IFERROR(SUMIFS(Data!$F:$F,Data!$B:$B,"อโศก",Data!$C:$C,"ITEM0179",Data!$A:$A,DATE(2026,5,2)),"") | E6: =IFERROR(SUMIFS(Data!$F:$F,Data!$B:$B,"อโศก",Data!$C:$C,"ITEM0179",Data!$A:$A,DATE(2026,5,3)),"") | F6: =IFERROR(SUMIFS(Data!$F:$F,Data!$B:$B,"อโศก",Data!$C:$C,"ITEM0179",Data!$A:$A,DATE(2026,5,4)),"") | G6: =IFERROR(SUMIFS(Data!$F:$F,Data!$B:$B,"อโศก",Data!$C:$C,"ITEM0179",Data!$A:$A,DATE(2026,5,5)),"") | H6: =IFERROR(SUMIFS(Data!$F:$F,Data!$B:$B,"อโศก",Data!$C:$C,"ITEM0179",Data!$A:$A,DATE(2026,5,6)),"") | I6: =IFERROR(SUMIFS(Data!$F:$F,Data!$B:$B,"อโศก",Data!$C:$C,"ITEM0179",Data!$A:$A,DATE(2026,5,7)),"") | J6: =IFERROR(SUMIFS(Data!$F:$F,Data!$B:$B,"อโศก",Data!$C:$C,"ITEM0179",Data!$A:$A,DATE(2026,5,8)),"") | K6: =IFERROR(SUMIFS(Data!$F:$F,Data!$B:$B,"อโศก",Data!$C:$C,"ITEM0179",Data!$A:$A,DATE(2026,5,9)),"") | L6: =IFERROR(SUMIFS(Data!$F:$F,Data!$B:$B,"อโศก",Data!$C:$C,"ITEM0179",Data!$A:$A,DATE(2026,5,10)),"") | M6: =IFERROR(SUMIFS(Data!$F:$F,Data!$B:$B,"อโศก",Data!$C:$C,"ITEM0179",Data!$A:$A,DATE(2026,5,11)),"") | N6: =IFERROR(SUMIFS(Data!$F:$F,Data!$B:$B,"อโศก",Data!$C:$C,"ITEM0179",Data!$A:$A,DATE(2026,5,12)),"") | O6: =IFERROR(SUMIFS(Data!$F:$F,Data!$B:$B,"อโศก",Data!$C:$C,"ITEM0179",Data!$A:$A,DATE(2026,5,13)),"") | P6: =IFERROR(SUMIFS(Data!$F:$F,Data!$B:$B,"อโศก",Data!$C:$C,"ITEM0179",Data!$A:$A,DATE(2026,5,14)),"") | Q6: =IFERROR(SUMIFS(Data!$F:$F,Data!$B:$B,"อโศก",Data!$C:$C,"ITEM0179",Data!$A:$A,DATE(2026,5,15)),"") | R6: =IFERROR(SUMIFS(Data!$F:$F,Data!$B:$B,"อโศก",Data!$C:$C,"ITEM0179",Data!$A:$A,DATE(2026,5,16)),"") | S6: =IFERROR(SUMIFS(Data!$F:$F,Data!$B:$B,"อโศก",Data!$C:$C,"ITEM0179",Data!$A:$A,DATE(2026,5,17)),"") | T6: =IFERROR(SUMIFS(Data!$F:$F,Data!$B:$B,"อโศก",Data!$C:$C,"ITEM0179",Data!$A:$A,DATE(2026,5,18)),"") | U6: =IFERROR(SUMIFS(Data!$F:$F,Data!$B:$B,"อโศก",Data!$C:$C,"ITEM0179",Data!$A:$A,DATE(2026,5,19)),"") | V6: =IFERROR(SUMIFS(Data!$F:$F,Data!$B:$B,"อโศก",Data!$C:$C,"ITEM0179",Data!$A:$A,DATE(2026,5,20)),"") | W6: =IFERROR(SUMIFS(Data!$F:$F,Data!$B:$B,"อโศก",Data!$C:$C,"ITEM0179",Data!$A:$A,DATE(2026,5,21)),"") | X6: =IFERROR(SUMIFS(Data!$F:$F,Data!$B:$B,"อโศก",Data!$C:$C,"ITEM0179",Data!$A:$A,DATE(2026,5,22)),"") | Y6: =IFERROR(SUMIFS(Data!$F:$F,Data!$B:$B,"อโศก",Data!$C:$C,"ITEM0179",Data!$A:$A,DATE(2026,5,23)),"") | Z6: =IFERROR(SUMIFS(Data!$F:$F,Data!$B:$B,"อโศก",Data!$C:$C,"ITEM0179",Data!$A:$A,DATE(2026,5,24)),"") | AA6: =IFERROR(SUMIFS(Data!$F:$F,Data!$B:$B,"อโศก",Data!$C:$C,"ITEM0179",Data!$A:$A,DATE(2026,5,25)),"") | AB6: =IFERROR(SUMIFS(Data!$F:$F,Data!$B:$B,"อโศก",Data!$C:$C,"ITEM0179",Data!$A:$A,DATE(2026,5,26)),"") | AC6: =IFERROR(SUMIFS(Data!$F:$F,Data!$B:$B,"อโศก",Data!$C:$C,"ITEM0179",Data!$A:$A,DATE(2026,5,27)),"") | AD6: =IFERROR(SUMIFS(Data!$F:$F,Data!$B:$B,"อโศก",Data!$C:$C,"ITEM0179",Data!$A:$A,DATE(2026,5,28)),"") | AE6: =IFERROR(SUMIFS(Data!$F:$F,Data!$B:$B,"อโศก",Data!$C:$C,"ITEM0179",Data!$A:$A,DATE(2026,5,29)),"") | AF6: =IFERROR(SUMIFS(Data!$F:$F,Data!$B:$B,"อโศก",Data!$C:$C,"ITEM0179",Data!$A:$A,DATE(2026,5,30)),"") | AG6: =IFERROR(SUMIFS(Data!$F:$F,Data!$B:$B,"อโศก",Data!$C:$C,"ITEM0179",Data!$A:$A,DATE(2026,5,31)),"") | AH6: =IFERROR(SUM(C6:AG6),0) | AI6: =AH6*15 | AJ6: =IFERROR(AI6/AI20,0)
A7: ITEM0180 | B7: 23 ค่าอาหาร (20 บาท) | C7: =IFERROR(SUMIFS(Data!$F:$F,Data!$B:$B,"อโศก",Data!$C:$C,"ITEM0180",Data!$A:$A,DATE(2026,5,1)),"") | D7: =IFERROR(SUMIFS(Data!$F:$F,Data!$B:$B,"อโศก",Data!$C:$C,"ITEM0180",Data!$A:$A,DATE(2026,5,2)),"") | E7: =IFERROR(SUMIFS(Data!$F:$F,Data!$B:$B,"อโศก",Data!$C:$C,"ITEM0180",Data!$A:$A,DATE(2026,5,3)),"") | F7: =IFERROR(SUMIFS(Data!$F:$F,Data!$B:$B,"อโศก",Data!$C:$C,"ITEM0180",Data!$A:$A,DATE(2026,5,4)),"") | G7: =IFERROR(SUMIFS(Data!$F:$F,Data!$B:$B,"อโศก",Data!$C:$C,"ITEM0180",Data!$A:$A,DATE(2026,5,5)),"") | H7: =IFERROR(SUMIFS(Data!$F:$F,Data!$B:$B,"อโศก",Data!$C:$C,"ITEM0180",Data!$A:$A,DATE(2026,5,6)),"") | I7: =IFERROR(SUMIFS(Data!$F:$F,Data!$B:$B,"อโศก",Data!$C:$C,"ITEM0180",Data!$A:$A,DATE(2026,5,7)),"") | J7: =IFERROR(SUMIFS(Data!$F:$F,Data!$B:$B,"อโศก",Data!$C:$C,"ITEM0180",Data!$A:$A,DATE(2026,5,8)),"") | K7: =IFERROR(SUMIFS(Data!$F:$F,Data!$B:$B,"อโศก",Data!$C:$C,"ITEM0180",Data!$A:$A,DATE(2026,5,9)),"") | L7: =IFERROR(SUMIFS(Data!$F:$F,Data!$B:$B,"อโศก",Data!$C:$C,"ITEM0180",Data!$A:$A,DATE(2026,5,10)),"") | M7: =IFERROR(SUMIFS(Data!$F:$F,Data!$B:$B,"อโศก",Data!$C:$C,"ITEM0180",Data!$A:$A,DATE(2026,5,11)),"") | N7: =IFERROR(SUMIFS(Data!$F:$F,Data!$B:$B,"อโศก",Data!$C:$C,"ITEM0180",Data!$A:$A,DATE(2026,5,12)),"") | O7: =IFERROR(SUMIFS(Data!$F:$F,Data!$B:$B,"อโศก",Data!$C:$C,"ITEM0180",Data!$A:$A,DATE(2026,5,13)),"") | P7: =IFERROR(SUMIFS(Data!$F:$F,Data!$B:$B,"อโศก",Data!$C:$C,"ITEM0180",Data!$A:$A,DATE(2026,5,14)),"") | Q7: =IFERROR(SUMIFS(Data!$F:$F,Data!$B:$B,"อโศก",Data!$C:$C,"ITEM0180",Data!$A:$A,DATE(2026,5,15)),"") | R7: =IFERROR(SUMIFS(Data!$F:$F,Data!$B:$B,"อโศก",Data!$C:$C,"ITEM0180",Data!$A:$A,DATE(2026,5,16)),"") | S7: =IFERROR(SUMIFS(Data!$F:$F,Data!$B:$B,"อโศก",Data!$C:$C,"ITEM0180",Data!$A:$A,DATE(2026,5,17)),"") | T7: =IFERROR(SUMIFS(Data!$F:$F,Data!$B:$B,"อโศก",Data!$C:$C,"ITEM0180",Data!$A:$A,DATE(2026,5,18)),"") | U7: =IFERROR(SUMIFS(Data!$F:$F,Data!$B:$B,"อโศก",Data!$C:$C,"ITEM0180",Data!$A:$A,DATE(2026,5,19)),"") | V7: =IFERROR(SUMIFS(Data!$F:$F,Data!$B:$B,"อโศก",Data!$C:$C,"ITEM0180",Data!$A:$A,DATE(2026,5,20)),"") | W7: =IFERROR(SUMIFS(Data!$F:$F,Data!$B:$B,"อโศก",Data!$C:$C,"ITEM0180",Data!$A:$A,DATE(2026,5,21)),"") | X7: =IFERROR(SUMIFS(Data!$F:$F,Data!$B:$B,"อโศก",Data!$C:$C,"ITEM0180",Data!$A:$A,DATE(2026,5,22)),"") | Y7: =IFERROR(SUMIFS(Data!$F:$F,Data!$B:$B,"อโศก",Data!$C:$C,"ITEM0180",Data!$A:$A,DATE(2026,5,23)),"") | Z7: =IFERROR(SUMIFS(Data!$F:$F,Data!$B:$B,"อโศก",Data!$C:$C,"ITEM0180",Data!$A:$A,DATE(2026,5,24)),"") | AA7: =IFERROR(SUMIFS(Data!$F:$F,Data!$B:$B,"อโศก",Data!$C:$C,"ITEM0180",Data!$A:$A,DATE(2026,5,25)),"") | AB7: =IFERROR(SUMIFS(Data!$F:$F,Data!$B:$B,"อโศก",Data!$C:$C,"ITEM0180",Data!$A:$A,DATE(2026,5,26)),"") | AC7: =IFERROR(SUMIFS(Data!$F:$F,Data!$B:$B,"อโศก",Data!$C:$C,"ITEM0180",Data!$A:$A,DATE(2026,5,27)),"") | AD7: =IFERROR(SUMIFS(Data!$F:$F,Data!$B:$B,"อโศก",Data!$C:$C,"ITEM0180",Data!$A:$A,DATE(2026,5,28)),"") | AE7: =IFERROR(SUMIFS(Data!$F:$F,Data!$B:$B,"อโศก",Data!$C:$C,"ITEM0180",Data!$A:$A,DATE(2026,5,29)),"") | AF7: =IFERROR(SUMIFS(Data!$F:$F,Data!$B:$B,"อโศก",Data!$C:$C,"ITEM0180",Data!$A:$A,DATE(2026,5,30)),"") | AG7: =IFERROR(SUMIFS(Data!$F:$F,Data!$B:$B,"อโศก",Data!$C:$C,"ITEM0180",Data!$A:$A,DATE(2026,5,31)),"") | AH7: =IFERROR(SUM(C7:AG7),0) | AI7: =AH7*20 | AJ7: =IFERROR(AI7/AI20,0)
A8: ITEM0181 | B8: 24 ค่าอาหาร (30 บาท) | C8: =IFERROR(SUMIFS(Data!$F:$F,Data!$B:$B,"อโศก",Data!$C:$C,"ITEM0181",Data!$A:$A,DATE(2026,5,1)),"") | D8: =IFERROR(SUMIFS(Data!$F:$F,Data!$B:$B,"อโศก",Data!$C:$C,"ITEM0181",Data!$A:$A,DATE(2026,5,2)),"") | E8: =IFERROR(SUMIFS(Data!$F:$F,Data!$B:$B,"อโศก",Data!$C:$C,"ITEM0181",Data!$A:$A,DATE(2026,5,3)),"") | F8: =IFERROR(SUMIFS(Data!$F:$F,Data!$B:$B,"อโศก",Data!$C:$C,"ITEM0181",Data!$A:$A,DATE(2026,5,4)),"") | G8: =IFERROR(SUMIFS(Data!$F:$F,Data!$B:$B,"อโศก",Data!$C:$C,"ITEM0181",Data!$A:$A,DATE(2026,5,5)),"") | H8: =IFERROR(SUMIFS(Data!$F:$F,Data!$B:$B,"อโศก",Data!$C:$C,"ITEM0181",Data!$A:$A,DATE(2026,5,6)),"") | I8: =IFERROR(SUMIFS(Data!$F:$F,Data!$B:$B,"อโศก",Data!$C:$C,"ITEM0181",Data!$A:$A,DATE(2026,5,7)),"") | J8: =IFERROR(SUMIFS(Data!$F:$F,Data!$B:$B,"อโศก",Data!$C:$C,"ITEM0181",Data!$A:$A,DATE(2026,5,8)),"") | K8: =IFERROR(SUMIFS(Data!$F:$F,Data!$B:$B,"อโศก",Data!$C:$C,"ITEM0181",Data!$A:$A,DATE(2026,5,9)),"") | L8: =IFERROR(SUMIFS(Data!$F:$F,Data!$B:$B,"อโศก",Data!$C:$C,"ITEM0181",Data!$A:$A,DATE(2026,5,10)),"") | M8: =IFERROR(SUMIFS(Data!$F:$F,Data!$B:$B,"อโศก",Data!$C:$C,"ITEM0181",Data!$A:$A,DATE(2026,5,11)),"") | N8: =IFERROR(SUMIFS(Data!$F:$F,Data!$B:$B,"อโศก",Data!$C:$C,"ITEM0181",Data!$A:$A,DATE(2026,5,12)),"") | O8: =IFERROR(SUMIFS(Data!$F:$F,Data!$B:$B,"อโศก",Data!$C:$C,"ITEM0181",Data!$A:$A,DATE(2026,5,13)),"") | P8: =IFERROR(SUMIFS(Data!$F:$F,Data!$B:$B,"อโศก",Data!$C:$C,"ITEM0181",Data!$A:$A,DATE(2026,5,14)),"") | Q8: =IFERROR(SUMIFS(Data!$F:$F,Data!$B:$B,"อโศก",Data!$C:$C,"ITEM0181",Data!$A:$A,DATE(2026,5,15)),"") | R8: =IFERROR(SUMIFS(Data!$F:$F,Data!$B:$B,"อโศก",Data!$C:$C,"ITEM0181",Data!$A:$A,DATE(2026,5,16)),"") | S8: =IFERROR(SUMIFS(Data!$F:$F,Data!$B:$B,"อโศก",Data!$C:$C,"ITEM0181",Data!$A:$A,DATE(2026,5,17)),"") | T8: =IFERROR(SUMIFS(Data!$F:$F,Data!$B:$B,"อโศก",Data!$C:$C,"ITEM0181",Data!$A:$A,DATE(2026,5,18)),"") | U8: =IFERROR(SUMIFS(Data!$F:$F,Data!$B:$B,"อโศก",Data!$C:$C,"ITEM0181",Data!$A:$A,DATE(2026,5,19)),"") | V8: =IFERROR(SUMIFS(Data!$F:$F,Data!$B:$B,"อโศก",Data!$C:$C,"ITEM0181",Data!$A:$A,DATE(2026,5,20)),"") | W8: =IFERROR(SUMIFS(Data!$F:$F,Data!$B:$B,"อโศก",Data!$C:$C,"ITEM0181",Data!$A:$A,DATE(2026,5,21)),"") | X8: =IFERROR(SUMIFS(Data!$F:$F,Data!$B:$B,"อโศก",Data!$C:$C,"ITEM0181",Data!$A:$A,DATE(2026,5,22)),"") | Y8: =IFERROR(SUMIFS(Data!$F:$F,Data!$B:$B,"อโศก",Data!$C:$C,"ITEM0181",Data!$A:$A,DATE(2026,5,23)),"") | Z8: =IFERROR(SUMIFS(Data!$F:$F,Data!$B:$B,"อโศก",Data!$C:$C,"ITEM0181",Data!$A:$A,DATE(2026,5,24)),"") | AA8: =IFERROR(SUMIFS(Data!$F:$F,Data!$B:$B,"อโศก",Data!$C:$C,"ITEM0181",Data!$A:$A,DATE(2026,5,25)),"") | AB8: =IFERROR(SUMIFS(Data!$F:$F,Data!$B:$B,"อโศก",Data!$C:$C,"ITEM0181",Data!$A:$A,DATE(2026,5,26)),"") | AC8: =IFERROR(SUMIFS(Data!$F:$F,Data!$B:$B,"อโศก",Data!$C:$C,"ITEM0181",Data!$A:$A,DATE(2026,5,27)),"") | AD8: =IFERROR(SUMIFS(Data!$F:$F,Data!$B:$B,"อโศก",Data!$C:$C,"ITEM0181",Data!$A:$A,DATE(2026,5,28)),"") | AE8: =IFERROR(SUMIFS(Data!$F:$F,Data!$B:$B,"อโศก",Data!$C:$C,"ITEM0181",Data!$A:$A,DATE(2026,5,29)),"") | AF8: =IFERROR(SUMIFS(Data!$F:$F,Data!$B:$B,"อโศก",Data!$C:$C,"ITEM0181",Data!$A:$A,DATE(2026,5,30)),"") | AG8: =IFERROR(SUMIFS(Data!$F:$F,Data!$B:$B,"อโศก",Data!$C:$C,"ITEM0181",Data!$A:$A,DATE(2026,5,31)),"") | AH8: =IFERROR(SUM(C8:AG8),0) | AI8: =AH8*30 | AJ8: =IFERROR(AI8/AI20,0)
A9: ITEM0941 | B9: ข้าวมันไก่สิงคโปร์ | C9: =IFERROR(SUMIFS(Data!$F:$F,Data!$B:$B,"อโศก",Data!$C:$C,"ITEM0941",Data!$A:$A,DATE(2026,5,1)),"") | D9: =IFERROR(SUMIFS(Data!$F:$F,Data!$B:$B,"อโศก",Data!$C:$C,"ITEM0941",Data!$A:$A,DATE(2026,5,2)),"") | E9: =IFERROR(SUMIFS(Data!$F:$F,Data!$B:$B,"อโศก",Data!$C:$C,"ITEM0941",Data!$A:$A,DATE(2026,5,3)),"") | F9: =IFERROR(SUMIFS(Data!$F:$F,Data!$B:$B,"อโศก",Data!$C:$C,"ITEM0941",Data!$A:$A,DATE(2026,5,4)),"") | G9: =IFERROR(SUMIFS(Data!$F:$F,Data!$B:$B,"อโศก",Data!$C:$C,"ITEM0941",Data!$A:$A,DATE(2026,5,5)),"") | H9: =IFERROR(SUMIFS(Data!$F:$F,Data!$B:$B,"อโศก",Data!$C:$C,"ITEM0941",Data!$A:$A,DATE(2026,5,6)),"") | I9: =IFERROR(SUMIFS(Data!$F:$F,Data!$B:$B,"อโศก",Data!$C:$C,"ITEM0941",Data!$A:$A,DATE(2026,5,7)),"") | J9: =IFERROR(SUMIFS(Data!$F:$F,Data!$B:$B,"อโศก",Data!$C:$C,"ITEM0941",Data!$A:$A,DATE(2026,5,8)),"") | K9: =IFERROR(SUMIFS(Data!$F:$F,Data!$B:$B,"อโศก",Data!$C:$C,"ITEM0941",Data!$A:$A,DATE(2026,5,9)),"") | L9: =IFERROR(SUMIFS(Data!$F:$F,Data!$B:$B,"อโศก",Data!$C:$C,"ITEM0941",Data!$A:$A,DATE(2026,5,10)),"") | M9: =IFERROR(SUMIFS(Data!$F:$F,Data!$B:$B,"อโศก",Data!$C:$C,"ITEM0941",Data!$A:$A,DATE(2026,5,11)),"") | N9: =IFERROR(SUMIFS(Data!$F:$F,Data!$B:$B,"อโศก",Data!$C:$C,"ITEM0941",Data!$A:$A,DATE(2026,5,12)),"") | O9: =IFERROR(SUMIFS(Data!$F:$F,Data!$B:$B,"อโศก",Data!$C:$C,"ITEM0941",Data!$A:$A,DATE(2026,5,13)),"") | P9: =IFERROR(SUMIFS(Data!$F:$F,Data!$B:$B,"อโศก",Data!$C:$C,"ITEM0941",Data!$A:$A,DATE(2026,5,14)),"") | Q9: =IFERROR(SUMIFS(Data!$F:$F,Data!$B:$B,"อโศก",Data!$C:$C,"ITEM0941",Data!$A:$A,DATE(2026,5,15)),"") | R9: =IFERROR(SUMIFS(Data!$F:$F,Data!$B:$B,"อโศก",Data!$C:$C,"ITEM0941",Data!$A:$A,DATE(2026,5,16)),"") | S9: =IFERROR(SUMIFS(Data!$F:$F,Data!$B:$B,"อโศก",Data!$C:$C,"ITEM0941",Data!$A:$A,DATE(2026,5,17)),"") | T9: =IFERROR(SUMIFS(Data!$F:$F,Data!$B:$B,"อโศก",Data!$C:$C,"ITEM0941",Data!$A:$A,DATE(2026,5,18)),"") | U9: =IFERROR(SUMIFS(Data!$F:$F,Data!$B:$B,"อโศก",Data!$C:$C,"ITEM0941",Data!$A:$A,DATE(2026,5,19)),"") | V9: =IFERROR(SUMIFS(Data!$F:$F,Data!$B:$B,"อโศก",Data!$C:$C,"ITEM0941",Data!$A:$A,DATE(2026,5,20)),"") | W9: =IFERROR(SUMIFS(Data!$F:$F,Data!$B:$B,"อโศก",Data!$C:$C,"ITEM0941",Data!$A:$A,DATE(2026,5,21)),"") | X9: =IFERROR(SUMIFS(Data!$F:$F,Data!$B:$B,"อโศก",Data!$C:$C,"ITEM0941",Data!$A:$A,DATE(2026,5,22)),"") | Y9: =IFERROR(SUMIFS(Data!$F:$F,Data!$B:$B,"อโศก",Data!$C:$C,"ITEM0941",Data!$A:$A,DATE(2026,5,23)),"") | Z9: =IFERROR(SUMIFS(Data!$F:$F,Data!$B:$B,"อโศก",Data!$C:$C,"ITEM0941",Data!$A:$A,DATE(2026,5,24)),"") | AA9: =IFERROR(SUMIFS(Data!$F:$F,Data!$B:$B,"อโศก",Data!$C:$C,"ITEM0941",Data!$A:$A,DATE(2026,5,25)),"") | AB9: =IFERROR(SUMIFS(Data!$F:$F,Data!$B:$B,"อโศก",Data!$C:$C,"ITEM0941",Data!$A:$A,DATE(2026,5,26)),"") | AC9: =IFERROR(SUMIFS(Data!$F:$F,Data!$B:$B,"อโศก",Data!$C:$C,"ITEM0941",Data!$A:$A,DATE(2026,5,27)),"") | AD9: =IFERROR(SUMIFS(Data!$F:$F,Data!$B:$B,"อโศก",Data!$C:$C,"ITEM0941",Data!$A:$A,DATE(2026,5,28)),"") | AE9: =IFERROR(SUMIFS(Data!$F:$F,Data!$B:$B,"อโศก",Data!$C:$C,"ITEM0941",Data!$A:$A,DATE(2026,5,29)),"") | AF9: =IFERROR(SUMIFS(Data!$F:$F,Data!$B:$B,"อโศก",Data!$C:$C,"ITEM0941",Data!$A:$A,DATE(2026,5,30)),"") | AG9: =IFERROR(SUMIFS(Data!$F:$F,Data!$B:$B,"อโศก",Data!$C:$C,"ITEM0941",Data!$A:$A,DATE(2026,5,31)),"") | AH9: =IFERROR(SUM(C9:AG9),0) | AI9: =AH9*57 | AJ9: =IFERROR(AI9/AI20,0)
A10: ITEM0942 | B10: ข้าวมันไก่ต้ม | C10: =IFERROR(SUMIFS(Data!$F:$F,Data!$B:$B,"อโศก",Data!$C:$C,"ITEM0942",Data!$A:$A,DATE(2026,5,1)),"") | D10: =IFERROR(SUMIFS(Data!$F:$F,Data!$B:$B,"อโศก",Data!$C:$C,"ITEM0942",Data!$A:$A,DATE(2026,5,2)),"") | E10: =IFERROR(SUMIFS(Data!$F:$F,Data!$B:$B,"อโศก",Data!$C:$C,"ITEM0942",Data!$A:$A,DATE(2026,5,3)),"") | F10: =IFERROR(SUMIFS(Data!$F:$F,Data!$B:$B,"อโศก",Data!$C:$C,"ITEM0942",Data!$A:$A,DATE(2026,5,4)),"") | G10: =IFERROR(SUMIFS(Data!$F:$F,Data!$B:$B,"อโศก",Data!$C:$C,"ITEM0942",Data!$A:$A,DATE(2026,5,5)),"") | H10: =IFERROR(SUMIFS(Data!$F:$F,Data!$B:$B,"อโศก",Data!$C:$C,"ITEM0942",Data!$A:$A,DATE(2026,5,6)),"") | I10: =IFERROR(SUMIFS(Data!$F:$F,Data!$B:$B,"อโศก",Data!$C:$C,"ITEM0942",Data!$A:$A,DATE(2026,5,7)),"") | J10: =IFERROR(SUMIFS(Data!$F:$F,Data!$B:$B,"อโศก",Data!$C:$C,"ITEM0942",Data!$A:$A,DATE(2026,5,8)),"") | K10: =IFERROR(SUMIFS(Data!$F:$F,Data!$B:$B,"อโศก",Data!$C:$C,"ITEM0942",Data!$A:$A,DATE(2026,5,9)),"") | L10: =IFERROR(SUMIFS(Data!$F:$F,Data!$B:$B,"อโศก",Data!$C:$C,"ITEM0942",Data!$A:$A,DATE(2026,5,10)),"") | M10: =IFERROR(SUMIFS(Data!$F:$F,Data!$B:$B,"อโศก",Data!$C:$C,"ITEM0942",Data!$A:$A,DATE(2026,5,11)),"") | N10: =IFERROR(SUMIFS(Data!$F:$F,Data!$B:$B,"อโศก",Data!$C:$C,"ITEM0942",Data!$A:$A,DATE(2026,5,12)),"") | O10: =IFERROR(SUMIFS(Data!$F:$F,Data!$B:$B,"อโศก",Data!$C:$C,"ITEM0942",Data!$A:$A,DATE(2026,5,13)),"") | P10: =IFERROR(SUMIFS(Data!$F:$F,Data!$B:$B,"อโศก",Data!$C:$C,"ITEM0942",Data!$A:$A,DATE(2026,5,14)),"") | Q10: =IFERROR(SUMIFS(Data!$F:$F,Data!$B:$B,"อโศก",Data!$C:$C,"ITEM0942",Data!$A:$A,DATE(2026,5,15)),"") | R10: =IFERROR(SUMIFS(Data!$F:$F,Data!$B:$B,"อโศก",Data!$C:$C,"ITEM0942",Data!$A:$A,DATE(2026,5,16)),"") | S10: =IFERROR(SUMIFS(Data!$F:$F,Data!$B:$B,"อโศก",Data!$C:$C,"ITEM0942",Data!$A:$A,DATE(2026,5,17)),"") | T10: =IFERROR(SUMIFS(Data!$F:$F,Data!$B:$B,"อโศก",Data!$C:$C,"ITEM0942",Data!$A:$A,DATE(2026,5,18)),"") | U10: =IFERROR(SUMIFS(Data!$F:$F,Data!$B:$B,"อโศก",Data!$C:$C,"ITEM0942",Data!$A:$A,DATE(2026,5,19)),"") | V10: =IFERROR(SUMIFS(Data!$F:$F,Data!$B:$B,"อโศก",Data!$C:$C,"ITEM0942",Data!$A:$A,DATE(2026,5,20)),"") | W10: =IFERROR(SUMIFS(Data!$F:$F,Data!$B:$B,"อโศก",Data!$C:$C,"ITEM0942",Data!$A:$A,DATE(2026,5,21)),"") | X10: =IFERROR(SUMIFS(Data!$F:$F,Data!$B:$B,"อโศก",Data!$C:$C,"ITEM0942",Data!$A:$A,DATE(2026,5,22)),"") | Y10: =IFERROR(SUMIFS(Data!$F:$F,Data!$B:$B,"อโศก",Data!$C:$C,"ITEM0942",Data!$A:$A,DATE(2026,5,23)),"") | Z10: =IFERROR(SUMIFS(Data!$F:$F,Data!$B:$B,"อโศก",Data!$C:$C,"ITEM0942",Data!$A:$A,DATE(2026,5,24)),"") | AA10: =IFERROR(SUMIFS(Data!$F:$F,Data!$B:$B,"อโศก",Data!$C:$C,"ITEM0942",Data!$A:$A,DATE(2026,5,25)),"") | AB10: =IFERROR(SUMIFS(Data!$F:$F,Data!$B:$B,"อโศก",Data!$C:$C,"ITEM0942",Data!$A:$A,DATE(2026,5,26)),"") | AC10: =IFERROR(SUMIFS(Data!$F:$F,Data!$B:$B,"อโศก",Data!$C:$C,"ITEM0942",Data!$A:$A,DATE(2026,5,27)),"") | AD10: =IFERROR(SUMIFS(Data!$F:$F,Data!$B:$B,"อโศก",Data!$C:$C,"ITEM0942",Data!$A:$A,DATE(2026,5,28)),"") | AE10: =IFERROR(SUMIFS(Data!$F:$F,Data!$B:$B,"อโศก",Data!$C:$C,"ITEM0942",Data!$A:$A,DATE(2026,5,29)),"") | AF10: =IFERROR(SUMIFS(Data!$F:$F,Data!$B:$B,"อโศก",Data!$C:$C,"ITEM0942",Data!$A:$A,DATE(2026,5,30)),"") | AG10: =IFERROR(SUMIFS(Data!$F:$F,Data!$B:$B,"อโศก",Data!$C:$C,"ITEM0942",Data!$A:$A,DATE(2026,5,31)),"") | AH10: =IFERROR(SUM(C10:AG10),0) | AI10: =AH10*35 | AJ10: =IFERROR(AI10/AI20,0)
A11: ITEM0943 | B11: ข้าวมันไก่ทอด | C11: =IFERROR(SUMIFS(Data!$F:$F,Data!$B:$B,"อโศก",Data!$C:$C,"ITEM0943",Data!$A:$A,DATE(2026,5,1)),"") | D11: =IFERROR(SUMIFS(Data!$F:$F,Data!$B:$B,"อโศก",Data!$C:$C,"ITEM0943",Data!$A:$A,DATE(2026,5,2)),"") | E11: =IFERROR(SUMIFS(Data!$F:$F,Data!$B:$B,"อโศก",Data!$C:$C,"ITEM0943",Data!$A:$A,DATE(2026,5,3)),"") | F11: =IFERROR(SUMIFS(Data!$F:$F,Data!$B:$B,"อโศก",Data!$C:$C,"ITEM0943",Data!$A:$A,DATE(2026,5,4)),"") | G11: =IFERROR(SUMIFS(Data!$F:$F,Data!$B:$B,"อโศก",Data!$C:$C,"ITEM0943",Data!$A:$A,DATE(2026,5,5)),"") | H11: =IFERROR(SUMIFS(Data!$F:$F,Data!$B:$B,"อโศก",Data!$C:$C,"ITEM0943",Data!$A:$A,DATE(2026,5,6)),"") | I11: =IFERROR(SUMIFS(Data!$F:$F,Data!$B:$B,"อโศก",Data!$C:$C,"ITEM0943",Data!$A:$A,DATE(2026,5,7)),"") | J11: =IFERROR(SUMIFS(Data!$F:$F,Data!$B:$B,"อโศก",Data!$C:$C,"ITEM0943",Data!$A:$A,DATE(2026,5,8)),"") | K11: =IFERROR(SUMIFS(Data!$F:$F,Data!$B:$B,"อโศก",Data!$C:$C,"ITEM0943",Data!$A:$A,DATE(2026,5,9)),"") | L11: =IFERROR(SUMIFS(Data!$F:$F,Data!$B:$B,"อโศก",Data!$C:$C,"ITEM0943",Data!$A:$A,DATE(2026,5,10)),"") | M11: =IFERROR(SUMIFS(Data!$F:$F,Data!$B:$B,"อโศก",Data!$C:$C,"ITEM0943",Data!$A:$A,DATE(2026,5,11)),"") | N11: =IFERROR(SUMIFS(Data!$F:$F,Data!$B:$B,"อโศก",Data!$C:$C,"ITEM0943",Data!$A:$A,DATE(2026,5,12)),"") | O11: =IFERROR(SUMIFS(Data!$F:$F,Data!$B:$B,"อโศก",Data!$C:$C,"ITEM0943",Data!$A:$A,DATE(2026,5,13)),"") | P11: =IFERROR(SUMIFS(Data!$F:$F,Data!$B:$B,"อโศก",Data!$C:$C,"ITEM0943",Data!$A:$A,DATE(2026,5,14)),"") | Q11: =IFERROR(SUMIFS(Data!$F:$F,Data!$B:$B,"อโศก",Data!$C:$C,"ITEM0943",Data!$A:$A,DATE(2026,5,15)),"") | R11: =IFERROR(SUMIFS(Data!$F:$F,Data!$B:$B,"อโศก",Data!$C:$C,"ITEM0943",Data!$A:$A,DATE(2026,5,16)),"") | S11: =IFERROR(SUMIFS(Data!$F:$F,Data!$B:$B,"อโศก",Data!$C:$C,"ITEM0943",Data!$A:$A,DATE(2026,5,17)),"") | T11: =IFERROR(SUMIFS(Data!$F:$F,Data!$B:$B,"อโศก",Data!$C:$C,"ITEM0943",Data!$A:$A,DATE(2026,5,18)),"") | U11: =IFERROR(SUMIFS(Data!$F:$F,Data!$B:$B,"อโศก",Data!$C:$C,"ITEM0943",Data!$A:$A,DATE(2026,5,19)),"") | V11: =IFERROR(SUMIFS(Data!$F:$F,Data!$B:$B,"อโศก",Data!$C:$C,"ITEM0943",Data!$A:$A,DATE(2026,5,20)),"") | W11: =IFERROR(SUMIFS(Data!$F:$F,Data!$B:$B,"อโศก",Data!$C:$C,"ITEM0943",Data!$A:$A,DATE(2026,5,21)),"") | X11: =IFERROR(SUMIFS(Data!$F:$F,Data!$B:$B,"อโศก",Data!$C:$C,"ITEM0943",Data!$A:$A,DATE(2026,5,22)),"") | Y11: =IFERROR(SUMIFS(Data!$F:$F,Data!$B:$B,"อโศก",Data!$C:$C,"ITEM0943",Data!$A:$A,DATE(2026,5,23)),"") | Z11: =IFERROR(SUMIFS(Data!$F:$F,Data!$B:$B,"อโศก",Data!$C:$C,"ITEM0943",Data!$A:$A,DATE(2026,5,24)),"") | AA11: =IFERROR(SUMIFS(Data!$F:$F,Data!$B:$B,"อโศก",Data!$C:$C,"ITEM0943",Data!$A:$A,DATE(2026,5,25)),"") | AB11: =IFERROR(SUMIFS(Data!$F:$F,Data!$B:$B,"อโศก",Data!$C:$C,"ITEM0943",Data!$A:$A,DATE(2026,5,26)),"") | AC11: =IFERROR(SUMIFS(Data!$F:$F,Data!$B:$B,"อโศก",Data!$C:$C,"ITEM0943",Data!$A:$A,DATE(2026,5,27)),"") | AD11: =IFERROR(SUMIFS(Data!$F:$F,Data!$B:$B,"อโศก",Data!$C:$C,"ITEM0943",Data!$A:$A,DATE(2026,5,28)),"") | AE11: =IFERROR(SUMIFS(Data!$F:$F,Data!$B:$B,"อโศก",Data!$C:$C,"ITEM0943",Data!$A:$A,DATE(2026,5,29)),"") | AF11: =IFERROR(SUMIFS(Data!$F:$F,Data!$B:$B,"อโศก",Data!$C:$C,"ITEM0943",Data!$A:$A,DATE(2026,5,30)),"") | AG11: =IFERROR(SUMIFS(Data!$F:$F,Data!$B:$B,"อโศก",Data!$C:$C,"ITEM0943",Data!$A:$A,DATE(2026,5,31)),"") | AH11: =IFERROR(SUM(C11:AG11),0) | AI11: =AH11*35 | AJ11: =IFERROR(AI11/AI20,0)
A12: ITEM0944 | B12: ข้าวมันไก่ผสม | C12: =IFERROR(SUMIFS(Data!$F:$F,Data!$B:$B,"อโศก",Data!$C:$C,"ITEM0944",Data!$A:$A,DATE(2026,5,1)),"") | D12: =IFERROR(SUMIFS(Data!$F:$F,Data!$B:$B,"อโศก",Data!$C:$C,"ITEM0944",Data!$A:$A,DATE(2026,5,2)),"") | E12: =IFERROR(SUMIFS(Data!$F:$F,Data!$B:$B,"อโศก",Data!$C:$C,"ITEM0944",Data!$A:$A,DATE(2026,5,3)),"") | F12: =IFERROR(SUMIFS(Data!$F:$F,Data!$B:$B,"อโศก",Data!$C:$C,"ITEM0944",Data!$A:$A,DATE(2026,5,4)),"") | G12: =IFERROR(SUMIFS(Data!$F:$F,Data!$B:$B,"อโศก",Data!$C:$C,"ITEM0944",Data!$A:$A,DATE(2026,5,5)),"") | H12: =IFERROR(SUMIFS(Data!$F:$F,Data!$B:$B,"อโศก",Data!$C:$C,"ITEM0944",Data!$A:$A,DATE(2026,5,6)),"") | I12: =IFERROR(SUMIFS(Data!$F:$F,Data!$B:$B,"อโศก",Data!$C:$C,"ITEM0944",Data!$A:$A,DATE(2026,5,7)),"") | J12: =IFERROR(SUMIFS(Data!$F:$F,Data!$B:$B,"อโศก",Data!$C:$C,"ITEM0944",Data!$A:$A,DATE(2026,5,8)),"") | K12: =IFERROR(SUMIFS(Data!$F:$F,Data!$B:$B,"อโศก",Data!$C:$C,"ITEM0944",Data!$A:$A,DATE(2026,5,9)),"") | L12: =IFERROR(SUMIFS(Data!$F:$F,Data!$B:$B,"อโศก",Data!$C:$C,"ITEM0944",Data!$A:$A,DATE(2026,5,10)),"") | M12: =IFERROR(SUMIFS(Data!$F:$F,Data!$B:$B,"อโศก",Data!$C:$C,"ITEM0944",Data!$A:$A,DATE(2026,5,11)),"") | N12: =IFERROR(SUMIFS(Data!$F:$F,Data!$B:$B,"อโศก",Data!$C:$C,"ITEM0944",Data!$A:$A,DATE(2026,5,12)),"") | O12: =IFERROR(SUMIFS(Data!$F:$F,Data!$B:$B,"อโศก",Data!$C:$C,"ITEM0944",Data!$A:$A,DATE(2026,5,13)),"") | P12: =IFERROR(SUMIFS(Data!$F:$F,Data!$B:$B,"อโศก",Data!$C:$C,"ITEM0944",Data!$A:$A,DATE(2026,5,14)),"") | Q12: =IFERROR(SUMIFS(Data!$F:$F,Data!$B:$B,"อโศก",Data!$C:$C,"ITEM0944",Data!$A:$A,DATE(2026,5,15)),"") | R12: =IFERROR(SUMIFS(Data!$F:$F,Data!$B:$B,"อโศก",Data!$C:$C,"ITEM0944",Data!$A:$A,DATE(2026,5,16)),"") | S12: =IFERROR(SUMIFS(Data!$F:$F,Data!$B:$B,"อโศก",Data!$C:$C,"ITEM0944",Data!$A:$A,DATE(2026,5,17)),"") | T12: =IFERROR(SUMIFS(Data!$F:$F,Data!$B:$B,"อโศก",Data!$C:$C,"ITEM0944",Data!$A:$A,DATE(2026,5,18)),"") | U12: =IFERROR(SUMIFS(Data!$F:$F,Data!$B:$B,"อโศก",Data!$C:$C,"ITEM0944",Data!$A:$A,DATE(2026,5,19)),"") | V12: =IFERROR(SUMIFS(Data!$F:$F,Data!$B:$B,"อโศก",Data!$C:$C,"ITEM0944",Data!$A:$A,DATE(2026,5,20)),"") | W12: =IFERROR(SUMIFS(Data!$F:$F,Data!$B:$B,"อโศก",Data!$C:$C,"ITEM0944",Data!$A:$A,DATE(2026,5,21)),"") | X12: =IFERROR(SUMIFS(Data!$F:$F,Data!$B:$B,"อโศก",Data!$C:$C,"ITEM0944",Data!$A:$A,DATE(2026,5,22)),"") | Y12: =IFERROR(SUMIFS(Data!$F:$F,Data!$B:$B,"อโศก",Data!$C:$C,"ITEM0944",Data!$A:$A,DATE(2026,5,23)),"") | Z12: =IFERROR(SUMIFS(Data!$F:$F,Data!$B:$B,"อโศก",Data!$C:$C,"ITEM0944",Data!$A:$A,DATE(2026,5,24)),"") | AA12: =IFERROR(SUMIFS(Data!$F:$F,Data!$B:$B,"อโศก",Data!$C:$C,"ITEM0944",Data!$A:$A,DATE(2026,5,25)),"") | AB12: =IFERROR(SUMIFS(Data!$F:$F,Data!$B:$B,"อโศก",Data!$C:$C,"ITEM0944",Data!$A:$A,DATE(2026,5,26)),"") | AC12: =IFERROR(SUMIFS(Data!$F:$F,Data!$B:$B,"อโศก",Data!$C:$C,"ITEM0944",Data!$A:$A,DATE(2026,5,27)),"") | AD12: =IFERROR(SUMIFS(Data!$F:$F,Data!$B:$B,"อโศก",Data!$C:$C,"ITEM0944",Data!$A:$A,DATE(2026,5,28)),"") | AE12: =IFERROR(SUMIFS(Data!$F:$F,Data!$B:$B,"อโศก",Data!$C:$C,"ITEM0944",Data!$A:$A,DATE(2026,5,29)),"") | AF12: =IFERROR(SUMIFS(Data!$F:$F,Data!$B:$B,"อโศก",Data!$C:$C,"ITEM0944",Data!$A:$A,DATE(2026,5,30)),"") | AG12: =IFERROR(SUMIFS(Data!$F:$F,Data!$B:$B,"อโศก",Data!$C:$C,"ITEM0944",Data!$A:$A,DATE(2026,5,31)),"") | AH12: =IFERROR(SUM(C12:AG12),0) | AI12: =AH12*40 | AJ12: =IFERROR(AI12/AI20,0)
A13: ITEM0945 | B13: ข้าวยำไก่แซ่บ | C13: =IFERROR(SUMIFS(Data!$F:$F,Data!$B:$B,"อโศก",Data!$C:$C,"ITEM0945",Data!$A:$A,DATE(2026,5,1)),"") | D13: =IFERROR(SUMIFS(Data!$F:$F,Data!$B:$B,"อโศก",Data!$C:$C,"ITEM0945",Data!$A:$A,DATE(2026,5,2)),"") | E13: =IFERROR(SUMIFS(Data!$F:$F,Data!$B:$B,"อโศก",Data!$C:$C,"ITEM0945",Data!$A:$A,DATE(2026,5,3)),"") | F13: =IFERROR(SUMIFS(Data!$F:$F,Data!$B:$B,"อโศก",Data!$C:$C,"ITEM0945",Data!$A:$A,DATE(2026,5,4)),"") | G13: =IFERROR(SUMIFS(Data!$F:$F,Data!$B:$B,"อโศก",Data!$C:$C,"ITEM0945",Data!$A:$A,DATE(2026,5,5)),"") | H13: =IFERROR(SUMIFS(Data!$F:$F,Data!$B:$B,"อโศก",Data!$C:$C,"ITEM0945",Data!$A:$A,DATE(2026,5,6)),"") | I13: =IFERROR(SUMIFS(Data!$F:$F,Data!$B:$B,"อโศก",Data!$C:$C,"ITEM0945",Data!$A:$A,DATE(2026,5,7)),"") | J13: =IFERROR(SUMIFS(Data!$F:$F,Data!$B:$B,"อโศก",Data!$C:$C,"ITEM0945",Data!$A:$A,DATE(2026,5,8)),"") | K13: =IFERROR(SUMIFS(Data!$F:$F,Data!$B:$B,"อโศก",Data!$C:$C,"ITEM0945",Data!$A:$A,DATE(2026,5,9)),"") | L13: =IFERROR(SUMIFS(Data!$F:$F,Data!$B:$B,"อโศก",Data!$C:$C,"ITEM0945",Data!$A:$A,DATE(2026,5,10)),"") | M13: =IFERROR(SUMIFS(Data!$F:$F,Data!$B:$B,"อโศก",Data!$C:$C,"ITEM0945",Data!$A:$A,DATE(2026,5,11)),"") | N13: =IFERROR(SUMIFS(Data!$F:$F,Data!$B:$B,"อโศก",Data!$C:$C,"ITEM0945",Data!$A:$A,DATE(2026,5,12)),"") | O13: =IFERROR(SUMIFS(Data!$F:$F,Data!$B:$B,"อโศก",Data!$C:$C,"ITEM0945",Data!$A:$A,DATE(2026,5,13)),"") | P13: =IFERROR(SUMIFS(Data!$F:$F,Data!$B:$B,"อโศก",Data!$C:$C,"ITEM0945",Data!$A:$A,DATE(2026,5,14)),"") | Q13: =IFERROR(SUMIFS(Data!$F:$F,Data!$B:$B,"อโศก",Data!$C:$C,"ITEM0945",Data!$A:$A,DATE(2026,5,15)),"") | R13: =IFERROR(SUMIFS(Data!$F:$F,Data!$B:$B,"อโศก",Data!$C:$C,"ITEM0945",Data!$A:$A,DATE(2026,5,16)),"") | S13: =IFERROR(SUMIFS(Data!$F:$F,Data!$B:$B,"อโศก",Data!$C:$C,"ITEM0945",Data!$A:$A,DATE(2026,5,17)),"") | T13: =IFERROR(SUMIFS(Data!$F:$F,Data!$B:$B,"อโศก",Data!$C:$C,"ITEM0945",Data!$A:$A,DATE(2026,5,18)),"") | U13: =IFERROR(SUMIFS(Data!$F:$F,Data!$B:$B,"อโศก",Data!$C:$C,"ITEM0945",Data!$A:$A,DATE(2026,5,19)),"") | V13: =IFERROR(SUMIFS(Data!$F:$F,Data!$B:$B,"อโศก",Data!$C:$C,"ITEM0945",Data!$A:$A,DATE(2026,5,20)),"") | W13: =IFERROR(SUMIFS(Data!$F:$F,Data!$B:$B,"อโศก",Data!$C:$C,"ITEM0945",Data!$A:$A,DATE(2026,5,21)),"") | X13: =IFERROR(SUMIFS(Data!$F:$F,Data!$B:$B,"อโศก",Data!$C:$C,"ITEM0945",Data!$A:$A,DATE(2026,5,22)),"") | Y13: =IFERROR(SUMIFS(Data!$F:$F,Data!$B:$B,"อโศก",Data!$C:$C,"ITEM0945",Data!$A:$A,DATE(2026,5,23)),"") | Z13: =IFERROR(SUMIFS(Data!$F:$F,Data!$B:$B,"อโศก",Data!$C:$C,"ITEM0945",Data!$A:$A,DATE(2026,5,24)),"") | AA13: =IFERROR(SUMIFS(Data!$F:$F,Data!$B:$B,"อโศก",Data!$C:$C,"ITEM0945",Data!$A:$A,DATE(2026,5,25)),"") | AB13: =IFERROR(SUMIFS(Data!$F:$F,Data!$B:$B,"อโศก",Data!$C:$C,"ITEM0945",Data!$A:$A,DATE(2026,5,26)),"") | AC13: =IFERROR(SUMIFS(Data!$F:$F,Data!$B:$B,"อโศก",Data!$C:$C,"ITEM0945",Data!$A:$A,DATE(2026,5,27)),"") | AD13: =IFERROR(SUMIFS(Data!$F:$F,Data!$B:$B,"อโศก",Data!$C:$C,"ITEM0945",Data!$A:$A,DATE(2026,5,28)),"") | AE13: =IFERROR(SUMIFS(Data!$F:$F,Data!$B:$B,"อโศก",Data!$C:$C,"ITEM0945",Data!$A:$A,DATE(2026,5,29)),"") | AF13: =IFERROR(SUMIFS(Data!$F:$F,Data!$B:$B,"อโศก",Data!$C:$C,"ITEM0945",Data!$A:$A,DATE(2026,5,30)),"") | AG13: =IFERROR(SUMIFS(Data!$F:$F,Data!$B:$B,"อโศก",Data!$C:$C,"ITEM0945",Data!$A:$A,DATE(2026,5,31)),"") | AH13: =IFERROR(SUM(C13:AG13),0) | AI13: =AH13*38 | AJ13: =IFERROR(AI13/AI20,0)
